ERROR 2022-04-25 10:41:48,446 views 47 用户admin1登录异常
[ERROR] 2022-04-25 10:46:42,655 views 47 用户admin1登录异常
[ERROR] 2022-04-25 10:47:13,639 views 47 用户admin1登录异常
[ERROR] 2022-04-25 15:13:30,389 views 54 用户admin登录异常
[ERROR] 2022-04-25 15:14:31,556 views 54 用户admin登录异常
[ERROR] 2022-04-25 15:16:38,911 views 54 Traceback (most recent call last):
  File "E:\Projects\djangoProjects\keep_healthy\users\views.py", line 50, in login
    return response_success('登录成功', res)
  File "E:\Projects\djangoProjects\keep_healthy\common\http_response.py", line 21, in response_success
    return result(HttpStatusCode.success, message=message, data=data)
  File "E:\Projects\djangoProjects\keep_healthy\common\http_response.py", line 17, in result
    return JsonResponse(json_dict, json_dumps_params={'ensure_ascii': False})
TypeError: keys must be str, int, float, bool or None, not Token

[ERROR] 2022-04-26 17:28:42,344 log 224 Internal Server Error: /users/logout
Traceback (most recent call last):
  File "D:\Application\Anaconda\envs\ML\lib\site-packages\django\core\handlers\exception.py", line 47, in inner
    response = get_response(request)
  File "D:\Application\Anaconda\envs\ML\lib\site-packages\django\utils\deprecation.py", line 116, in __call__
    response = self.process_request(request)
  File "D:\Application\Anaconda\envs\ML\lib\site-packages\django\middleware\common.py", line 54, in process_request
    path = self.get_full_path_with_slash(request)
  File "D:\Application\Anaconda\envs\ML\lib\site-packages\django\middleware\common.py", line 88, in get_full_path_with_slash
    raise RuntimeError(
RuntimeError: You called this URL via POST, but the URL doesn't end in a slash and you have APPEND_SLASH set. Django can't redirect to the slash URL while maintaining POST data. Change your form to point to 127.0.0.1:8000/users/logout/ (note the trailing slash), or set APPEND_SLASH=False in your Django settings.
[ERROR] 2022-04-26 17:30:07,439 log 224 Internal Server Error: /users/logout/
Traceback (most recent call last):
  File "D:\Application\Anaconda\envs\ML\lib\site-packages\django\core\handlers\exception.py", line 47, in inner
    response = get_response(request)
  File "D:\Application\Anaconda\envs\ML\lib\site-packages\django\core\handlers\base.py", line 181, in _get_response
    response = wrapped_callback(request, *callback_args, **callback_kwargs)
  File "D:\Application\Anaconda\envs\ML\lib\site-packages\django\views\decorators\csrf.py", line 54, in wrapped_view
    return view_func(*args, **kwargs)
  File "D:\Application\Anaconda\envs\ML\lib\site-packages\rest_framework\viewsets.py", line 125, in view
    return self.dispatch(request, *args, **kwargs)
  File "D:\Application\Anaconda\envs\ML\lib\site-packages\rest_framework\views.py", line 511, in dispatch
    self.response = self.finalize_response(request, response, *args, **kwargs)
  File "D:\Application\Anaconda\envs\ML\lib\site-packages\rest_framework\views.py", line 423, in finalize_response
    assert isinstance(response, HttpResponseBase), (
AssertionError: Expected a `Response`, `HttpResponse` or `HttpStreamingResponse` to be returned from the view, but received a `<class 'NoneType'>`
[ERROR] 2022-04-26 18:04:18,922 views 58 Traceback (most recent call last):
  File "D:\Application\Anaconda\envs\ML\lib\site-packages\django\db\backends\utils.py", line 84, in _execute
    return self.cursor.execute(sql, params)
  File "D:\Application\Anaconda\envs\ML\lib\site-packages\django\db\backends\mysql\base.py", line 73, in execute
    return self.cursor.execute(query, args)
  File "D:\Application\Anaconda\envs\ML\lib\site-packages\MySQLdb\cursors.py", line 206, in execute
    res = self._query(query)
MySQLdb._exceptions.IntegrityError: (1062, "Duplicate entry '1' for key 'user_id'")

The above exception was the direct cause of the following exception:

Traceback (most recent call last):
  File "E:\Projects\djangoProjects\keep_healthy\users\views.py", line 46, in login
    token = Token.objects.create(user=user)
  File "D:\Application\Anaconda\envs\ML\lib\site-packages\django\db\models\manager.py", line 85, in manager_method
    return getattr(self.get_queryset(), name)(*args, **kwargs)
  File "D:\Application\Anaconda\envs\ML\lib\site-packages\django\db\models\query.py", line 453, in create
    obj.save(force_insert=True, using=self.db)
django.db.utils.IntegrityError: (1062, "Duplicate entry '1' for key 'user_id'")

[ERROR] 2022-04-27 21:29:47,132 log 224 Internal Server Error: /diabetes/fetch_diabetes_data/
Traceback (most recent call last):
  File "D:\Application\Anaconda\envs\ML\lib\site-packages\django\core\handlers\exception.py", line 47, in inner
    response = get_response(request)
  File "D:\Application\Anaconda\envs\ML\lib\site-packages\django\core\handlers\base.py", line 181, in _get_response
    response = wrapped_callback(request, *callback_args, **callback_kwargs)
  File "D:\Application\Anaconda\envs\ML\lib\site-packages\django\views\decorators\csrf.py", line 54, in wrapped_view
    return view_func(*args, **kwargs)
  File "D:\Application\Anaconda\envs\ML\lib\site-packages\rest_framework\viewsets.py", line 125, in view
    return self.dispatch(request, *args, **kwargs)
  File "D:\Application\Anaconda\envs\ML\lib\site-packages\rest_framework\views.py", line 511, in dispatch
    self.response = self.finalize_response(request, response, *args, **kwargs)
  File "D:\Application\Anaconda\envs\ML\lib\site-packages\rest_framework\views.py", line 423, in finalize_response
    assert isinstance(response, HttpResponseBase), (
AssertionError: Expected a `Response`, `HttpResponse` or `HttpStreamingResponse` to be returned from the view, but received a `<class 'NoneType'>`
[ERROR] 2022-04-27 21:33:27,828 log 224 Internal Server Error: /diabetes/fetch_diabetes_data/
Traceback (most recent call last):
  File "D:\Application\Anaconda\envs\ML\lib\site-packages\django\core\handlers\exception.py", line 47, in inner
    response = get_response(request)
  File "D:\Application\Anaconda\envs\ML\lib\site-packages\django\core\handlers\base.py", line 181, in _get_response
    response = wrapped_callback(request, *callback_args, **callback_kwargs)
  File "D:\Application\Anaconda\envs\ML\lib\site-packages\django\views\decorators\csrf.py", line 54, in wrapped_view
    return view_func(*args, **kwargs)
  File "D:\Application\Anaconda\envs\ML\lib\site-packages\rest_framework\viewsets.py", line 125, in view
    return self.dispatch(request, *args, **kwargs)
  File "D:\Application\Anaconda\envs\ML\lib\site-packages\rest_framework\views.py", line 511, in dispatch
    self.response = self.finalize_response(request, response, *args, **kwargs)
  File "D:\Application\Anaconda\envs\ML\lib\site-packages\rest_framework\views.py", line 423, in finalize_response
    assert isinstance(response, HttpResponseBase), (
AssertionError: Expected a `Response`, `HttpResponse` or `HttpStreamingResponse` to be returned from the view, but received a `<class 'NoneType'>`
[ERROR] 2022-04-27 21:36:28,716 log 224 Internal Server Error: /diabetes/fetch_diabetes_data/
Traceback (most recent call last):
  File "D:\Application\Anaconda\envs\ML\lib\site-packages\django\core\handlers\exception.py", line 47, in inner
    response = get_response(request)
  File "D:\Application\Anaconda\envs\ML\lib\site-packages\django\core\handlers\base.py", line 181, in _get_response
    response = wrapped_callback(request, *callback_args, **callback_kwargs)
  File "D:\Application\Anaconda\envs\ML\lib\site-packages\django\views\decorators\csrf.py", line 54, in wrapped_view
    return view_func(*args, **kwargs)
  File "D:\Application\Anaconda\envs\ML\lib\site-packages\rest_framework\viewsets.py", line 125, in view
    return self.dispatch(request, *args, **kwargs)
  File "D:\Application\Anaconda\envs\ML\lib\site-packages\rest_framework\views.py", line 511, in dispatch
    self.response = self.finalize_response(request, response, *args, **kwargs)
  File "D:\Application\Anaconda\envs\ML\lib\site-packages\rest_framework\views.py", line 423, in finalize_response
    assert isinstance(response, HttpResponseBase), (
AssertionError: Expected a `Response`, `HttpResponse` or `HttpStreamingResponse` to be returned from the view, but received a `<class 'NoneType'>`
[ERROR] 2022-04-27 21:36:28,784 log 224 Internal Server Error: /diabetes/fetch_diabetes_data/
Traceback (most recent call last):
  File "D:\Application\Anaconda\envs\ML\lib\site-packages\django\core\handlers\exception.py", line 47, in inner
    response = get_response(request)
  File "D:\Application\Anaconda\envs\ML\lib\site-packages\django\core\handlers\base.py", line 181, in _get_response
    response = wrapped_callback(request, *callback_args, **callback_kwargs)
  File "D:\Application\Anaconda\envs\ML\lib\site-packages\django\views\decorators\csrf.py", line 54, in wrapped_view
    return view_func(*args, **kwargs)
  File "D:\Application\Anaconda\envs\ML\lib\site-packages\rest_framework\viewsets.py", line 125, in view
    return self.dispatch(request, *args, **kwargs)
  File "D:\Application\Anaconda\envs\ML\lib\site-packages\rest_framework\views.py", line 511, in dispatch
    self.response = self.finalize_response(request, response, *args, **kwargs)
  File "D:\Application\Anaconda\envs\ML\lib\site-packages\rest_framework\views.py", line 423, in finalize_response
    assert isinstance(response, HttpResponseBase), (
AssertionError: Expected a `Response`, `HttpResponse` or `HttpStreamingResponse` to be returned from the view, but received a `<class 'NoneType'>`
[ERROR] 2022-04-27 21:38:24,824 log 224 Internal Server Error: /diabetes/fetch_diabetes_data/
Traceback (most recent call last):
  File "D:\Application\Anaconda\envs\ML\lib\site-packages\django\core\handlers\exception.py", line 47, in inner
    response = get_response(request)
  File "D:\Application\Anaconda\envs\ML\lib\site-packages\django\core\handlers\base.py", line 181, in _get_response
    response = wrapped_callback(request, *callback_args, **callback_kwargs)
  File "D:\Application\Anaconda\envs\ML\lib\site-packages\django\views\decorators\csrf.py", line 54, in wrapped_view
    return view_func(*args, **kwargs)
  File "D:\Application\Anaconda\envs\ML\lib\site-packages\rest_framework\viewsets.py", line 125, in view
    return self.dispatch(request, *args, **kwargs)
  File "D:\Application\Anaconda\envs\ML\lib\site-packages\rest_framework\views.py", line 511, in dispatch
    self.response = self.finalize_response(request, response, *args, **kwargs)
  File "D:\Application\Anaconda\envs\ML\lib\site-packages\rest_framework\views.py", line 423, in finalize_response
    assert isinstance(response, HttpResponseBase), (
AssertionError: Expected a `Response`, `HttpResponse` or `HttpStreamingResponse` to be returned from the view, but received a `<class 'NoneType'>`
[ERROR] 2022-04-27 21:39:40,933 views 35 Traceback (most recent call last):
  File "E:\Projects\djangoProjects\keep_healthy\diabetes\views.py", line 29, in fetch_diabetes_data
    body = json.loads(request.body)
  File "D:\Application\Anaconda\envs\ML\lib\json\__init__.py", line 357, in loads
    return _default_decoder.decode(s)
  File "D:\Application\Anaconda\envs\ML\lib\json\decoder.py", line 337, in decode
    obj, end = self.raw_decode(s, idx=_w(s, 0).end())
json.decoder.JSONDecodeError: Expecting value: line 1 column 1 (char 0)

[ERROR] 2022-04-27 21:39:41,187 log 224 Internal Server Error: /diabetes/fetch_diabetes_data/
Traceback (most recent call last):
  File "D:\Application\Anaconda\envs\ML\lib\site-packages\django\core\handlers\exception.py", line 47, in inner
    response = get_response(request)
  File "D:\Application\Anaconda\envs\ML\lib\site-packages\django\core\handlers\base.py", line 181, in _get_response
    response = wrapped_callback(request, *callback_args, **callback_kwargs)
  File "D:\Application\Anaconda\envs\ML\lib\site-packages\django\views\decorators\csrf.py", line 54, in wrapped_view
    return view_func(*args, **kwargs)
  File "D:\Application\Anaconda\envs\ML\lib\site-packages\rest_framework\viewsets.py", line 125, in view
    return self.dispatch(request, *args, **kwargs)
  File "D:\Application\Anaconda\envs\ML\lib\site-packages\rest_framework\views.py", line 511, in dispatch
    self.response = self.finalize_response(request, response, *args, **kwargs)
  File "D:\Application\Anaconda\envs\ML\lib\site-packages\rest_framework\views.py", line 423, in finalize_response
    assert isinstance(response, HttpResponseBase), (
AssertionError: Expected a `Response`, `HttpResponse` or `HttpStreamingResponse` to be returned from the view, but received a `<class 'NoneType'>`
[ERROR] 2022-04-27 21:39:57,383 views 35 Traceback (most recent call last):
  File "E:\Projects\djangoProjects\keep_healthy\diabetes\views.py", line 29, in fetch_diabetes_data
    body = json.loads(request.body)
  File "D:\Application\Anaconda\envs\ML\lib\json\__init__.py", line 357, in loads
    return _default_decoder.decode(s)
  File "D:\Application\Anaconda\envs\ML\lib\json\decoder.py", line 337, in decode
    obj, end = self.raw_decode(s, idx=_w(s, 0).end())
json.decoder.JSONDecodeError: Expecting value: line 1 column 1 (char 0)

[ERROR] 2022-04-27 21:39:57,516 log 224 Internal Server Error: /diabetes/fetch_diabetes_data/
Traceback (most recent call last):
  File "D:\Application\Anaconda\envs\ML\lib\site-packages\django\core\handlers\exception.py", line 47, in inner
    response = get_response(request)
  File "D:\Application\Anaconda\envs\ML\lib\site-packages\django\core\handlers\base.py", line 181, in _get_response
    response = wrapped_callback(request, *callback_args, **callback_kwargs)
  File "D:\Application\Anaconda\envs\ML\lib\site-packages\django\views\decorators\csrf.py", line 54, in wrapped_view
    return view_func(*args, **kwargs)
  File "D:\Application\Anaconda\envs\ML\lib\site-packages\rest_framework\viewsets.py", line 125, in view
    return self.dispatch(request, *args, **kwargs)
  File "D:\Application\Anaconda\envs\ML\lib\site-packages\rest_framework\views.py", line 511, in dispatch
    self.response = self.finalize_response(request, response, *args, **kwargs)
  File "D:\Application\Anaconda\envs\ML\lib\site-packages\rest_framework\views.py", line 423, in finalize_response
    assert isinstance(response, HttpResponseBase), (
AssertionError: Expected a `Response`, `HttpResponse` or `HttpStreamingResponse` to be returned from the view, but received a `<class 'NoneType'>`
[ERROR] 2022-04-27 21:40:19,378 views 35 Traceback (most recent call last):
  File "E:\Projects\djangoProjects\keep_healthy\diabetes\views.py", line 29, in fetch_diabetes_data
    body = json.loads(request.body)
  File "D:\Application\Anaconda\envs\ML\lib\json\__init__.py", line 357, in loads
    return _default_decoder.decode(s)
  File "D:\Application\Anaconda\envs\ML\lib\json\decoder.py", line 337, in decode
    obj, end = self.raw_decode(s, idx=_w(s, 0).end())
json.decoder.JSONDecodeError: Expecting value: line 1 column 1 (char 0)

[ERROR] 2022-04-27 21:40:19,648 log 224 Internal Server Error: /diabetes/fetch_diabetes_data/
Traceback (most recent call last):
  File "D:\Application\Anaconda\envs\ML\lib\site-packages\django\core\handlers\exception.py", line 47, in inner
    response = get_response(request)
  File "D:\Application\Anaconda\envs\ML\lib\site-packages\django\core\handlers\base.py", line 181, in _get_response
    response = wrapped_callback(request, *callback_args, **callback_kwargs)
  File "D:\Application\Anaconda\envs\ML\lib\site-packages\django\views\decorators\csrf.py", line 54, in wrapped_view
    return view_func(*args, **kwargs)
  File "D:\Application\Anaconda\envs\ML\lib\site-packages\rest_framework\viewsets.py", line 125, in view
    return self.dispatch(request, *args, **kwargs)
  File "D:\Application\Anaconda\envs\ML\lib\site-packages\rest_framework\views.py", line 511, in dispatch
    self.response = self.finalize_response(request, response, *args, **kwargs)
  File "D:\Application\Anaconda\envs\ML\lib\site-packages\rest_framework\views.py", line 423, in finalize_response
    assert isinstance(response, HttpResponseBase), (
AssertionError: Expected a `Response`, `HttpResponse` or `HttpStreamingResponse` to be returned from the view, but received a `<class 'NoneType'>`
[ERROR] 2022-04-27 21:40:30,883 views 35 Traceback (most recent call last):
  File "E:\Projects\djangoProjects\keep_healthy\diabetes\views.py", line 29, in fetch_diabetes_data
    body = json.loads(request.body)
  File "D:\Application\Anaconda\envs\ML\lib\json\__init__.py", line 357, in loads
    return _default_decoder.decode(s)
  File "D:\Application\Anaconda\envs\ML\lib\json\decoder.py", line 337, in decode
    obj, end = self.raw_decode(s, idx=_w(s, 0).end())
json.decoder.JSONDecodeError: Expecting value: line 1 column 1 (char 0)

[ERROR] 2022-04-27 21:40:31,003 log 224 Internal Server Error: /diabetes/fetch_diabetes_data/
Traceback (most recent call last):
  File "D:\Application\Anaconda\envs\ML\lib\site-packages\django\core\handlers\exception.py", line 47, in inner
    response = get_response(request)
  File "D:\Application\Anaconda\envs\ML\lib\site-packages\django\core\handlers\base.py", line 181, in _get_response
    response = wrapped_callback(request, *callback_args, **callback_kwargs)
  File "D:\Application\Anaconda\envs\ML\lib\site-packages\django\views\decorators\csrf.py", line 54, in wrapped_view
    return view_func(*args, **kwargs)
  File "D:\Application\Anaconda\envs\ML\lib\site-packages\rest_framework\viewsets.py", line 125, in view
    return self.dispatch(request, *args, **kwargs)
  File "D:\Application\Anaconda\envs\ML\lib\site-packages\rest_framework\views.py", line 511, in dispatch
    self.response = self.finalize_response(request, response, *args, **kwargs)
  File "D:\Application\Anaconda\envs\ML\lib\site-packages\rest_framework\views.py", line 423, in finalize_response
    assert isinstance(response, HttpResponseBase), (
AssertionError: Expected a `Response`, `HttpResponse` or `HttpStreamingResponse` to be returned from the view, but received a `<class 'NoneType'>`
[ERROR] 2022-04-27 21:40:58,040 views 36 Traceback (most recent call last):
  File "E:\Projects\djangoProjects\keep_healthy\diabetes\views.py", line 29, in fetch_diabetes_data
    body = json.loads(request.body)
  File "D:\Application\Anaconda\envs\ML\lib\json\__init__.py", line 357, in loads
    return _default_decoder.decode(s)
  File "D:\Application\Anaconda\envs\ML\lib\json\decoder.py", line 337, in decode
    obj, end = self.raw_decode(s, idx=_w(s, 0).end())
json.decoder.JSONDecodeError: Expecting value: line 1 column 1 (char 0)

[ERROR] 2022-04-27 21:40:58,394 log 224 Internal Server Error: /diabetes/fetch_diabetes_data/
Traceback (most recent call last):
  File "D:\Application\Anaconda\envs\ML\lib\site-packages\django\core\handlers\exception.py", line 47, in inner
    response = get_response(request)
  File "D:\Application\Anaconda\envs\ML\lib\site-packages\django\core\handlers\base.py", line 181, in _get_response
    response = wrapped_callback(request, *callback_args, **callback_kwargs)
  File "D:\Application\Anaconda\envs\ML\lib\site-packages\django\views\decorators\csrf.py", line 54, in wrapped_view
    return view_func(*args, **kwargs)
  File "D:\Application\Anaconda\envs\ML\lib\site-packages\rest_framework\viewsets.py", line 125, in view
    return self.dispatch(request, *args, **kwargs)
  File "D:\Application\Anaconda\envs\ML\lib\site-packages\rest_framework\views.py", line 511, in dispatch
    self.response = self.finalize_response(request, response, *args, **kwargs)
  File "D:\Application\Anaconda\envs\ML\lib\site-packages\rest_framework\views.py", line 423, in finalize_response
    assert isinstance(response, HttpResponseBase), (
AssertionError: Expected a `Response`, `HttpResponse` or `HttpStreamingResponse` to be returned from the view, but received a `<class 'NoneType'>`
[ERROR] 2022-04-27 21:47:34,150 log 224 Internal Server Error: /diabetes/fetch_diabetes_data/
Traceback (most recent call last):
  File "D:\Application\Anaconda\envs\ML\lib\site-packages\django\core\handlers\exception.py", line 47, in inner
    response = get_response(request)
  File "D:\Application\Anaconda\envs\ML\lib\site-packages\django\core\handlers\base.py", line 181, in _get_response
    response = wrapped_callback(request, *callback_args, **callback_kwargs)
  File "D:\Application\Anaconda\envs\ML\lib\site-packages\django\views\decorators\csrf.py", line 54, in wrapped_view
    return view_func(*args, **kwargs)
  File "D:\Application\Anaconda\envs\ML\lib\site-packages\rest_framework\viewsets.py", line 125, in view
    return self.dispatch(request, *args, **kwargs)
  File "D:\Application\Anaconda\envs\ML\lib\site-packages\rest_framework\views.py", line 511, in dispatch
    self.response = self.finalize_response(request, response, *args, **kwargs)
  File "D:\Application\Anaconda\envs\ML\lib\site-packages\rest_framework\views.py", line 423, in finalize_response
    assert isinstance(response, HttpResponseBase), (
AssertionError: Expected a `Response`, `HttpResponse` or `HttpStreamingResponse` to be returned from the view, but received a `<class 'NoneType'>`
[ERROR] 2022-04-27 21:49:54,030 log 224 Internal Server Error: /diabetes/fetch_diabetes_data/
Traceback (most recent call last):
  File "D:\Application\Anaconda\envs\ML\lib\site-packages\django\core\handlers\exception.py", line 47, in inner
    response = get_response(request)
  File "D:\Application\Anaconda\envs\ML\lib\site-packages\django\core\handlers\base.py", line 181, in _get_response
    response = wrapped_callback(request, *callback_args, **callback_kwargs)
  File "D:\Application\Anaconda\envs\ML\lib\site-packages\django\views\decorators\csrf.py", line 54, in wrapped_view
    return view_func(*args, **kwargs)
  File "D:\Application\Anaconda\envs\ML\lib\site-packages\rest_framework\viewsets.py", line 125, in view
    return self.dispatch(request, *args, **kwargs)
  File "D:\Application\Anaconda\envs\ML\lib\site-packages\rest_framework\views.py", line 511, in dispatch
    self.response = self.finalize_response(request, response, *args, **kwargs)
  File "D:\Application\Anaconda\envs\ML\lib\site-packages\rest_framework\views.py", line 423, in finalize_response
    assert isinstance(response, HttpResponseBase), (
AssertionError: Expected a `Response`, `HttpResponse` or `HttpStreamingResponse` to be returned from the view, but received a `<class 'NoneType'>`
[ERROR] 2022-04-27 21:50:57,888 log 224 Internal Server Error: /diabetes/fetch_diabetes_data/
Traceback (most recent call last):
  File "D:\Application\Anaconda\envs\ML\lib\site-packages\django\core\handlers\exception.py", line 47, in inner
    response = get_response(request)
  File "D:\Application\Anaconda\envs\ML\lib\site-packages\django\core\handlers\base.py", line 181, in _get_response
    response = wrapped_callback(request, *callback_args, **callback_kwargs)
  File "D:\Application\Anaconda\envs\ML\lib\site-packages\django\views\decorators\csrf.py", line 54, in wrapped_view
    return view_func(*args, **kwargs)
  File "D:\Application\Anaconda\envs\ML\lib\site-packages\rest_framework\viewsets.py", line 125, in view
    return self.dispatch(request, *args, **kwargs)
  File "D:\Application\Anaconda\envs\ML\lib\site-packages\rest_framework\views.py", line 511, in dispatch
    self.response = self.finalize_response(request, response, *args, **kwargs)
  File "D:\Application\Anaconda\envs\ML\lib\site-packages\rest_framework\views.py", line 423, in finalize_response
    assert isinstance(response, HttpResponseBase), (
AssertionError: Expected a `Response`, `HttpResponse` or `HttpStreamingResponse` to be returned from the view, but received a `<class 'NoneType'>`
[ERROR] 2022-04-27 21:54:24,662 log 224 Internal Server Error: /diabetes/fetch_diabetes_data/
Traceback (most recent call last):
  File "D:\Application\Anaconda\envs\ML\lib\site-packages\django\core\handlers\exception.py", line 47, in inner
    response = get_response(request)
  File "D:\Application\Anaconda\envs\ML\lib\site-packages\django\core\handlers\base.py", line 181, in _get_response
    response = wrapped_callback(request, *callback_args, **callback_kwargs)
  File "D:\Application\Anaconda\envs\ML\lib\site-packages\django\views\decorators\csrf.py", line 54, in wrapped_view
    return view_func(*args, **kwargs)
  File "D:\Application\Anaconda\envs\ML\lib\site-packages\rest_framework\viewsets.py", line 125, in view
    return self.dispatch(request, *args, **kwargs)
  File "D:\Application\Anaconda\envs\ML\lib\site-packages\rest_framework\views.py", line 511, in dispatch
    self.response = self.finalize_response(request, response, *args, **kwargs)
  File "D:\Application\Anaconda\envs\ML\lib\site-packages\rest_framework\views.py", line 423, in finalize_response
    assert isinstance(response, HttpResponseBase), (
AssertionError: Expected a `Response`, `HttpResponse` or `HttpStreamingResponse` to be returned from the view, but received a `<class 'NoneType'>`
[ERROR] 2022-04-27 21:55:32,789 log 224 Internal Server Error: /diabetes/fetch_diabetes_data/
Traceback (most recent call last):
  File "D:\Application\Anaconda\envs\ML\lib\site-packages\django\core\handlers\exception.py", line 47, in inner
    response = get_response(request)
  File "D:\Application\Anaconda\envs\ML\lib\site-packages\django\core\handlers\base.py", line 181, in _get_response
    response = wrapped_callback(request, *callback_args, **callback_kwargs)
  File "D:\Application\Anaconda\envs\ML\lib\site-packages\django\views\decorators\csrf.py", line 54, in wrapped_view
    return view_func(*args, **kwargs)
  File "D:\Application\Anaconda\envs\ML\lib\site-packages\rest_framework\viewsets.py", line 125, in view
    return self.dispatch(request, *args, **kwargs)
  File "D:\Application\Anaconda\envs\ML\lib\site-packages\rest_framework\views.py", line 511, in dispatch
    self.response = self.finalize_response(request, response, *args, **kwargs)
  File "D:\Application\Anaconda\envs\ML\lib\site-packages\rest_framework\views.py", line 423, in finalize_response
    assert isinstance(response, HttpResponseBase), (
AssertionError: Expected a `Response`, `HttpResponse` or `HttpStreamingResponse` to be returned from the view, but received a `<class 'NoneType'>`
[ERROR] 2022-04-27 21:57:27,861 views 34 Traceback (most recent call last):
  File "E:\Projects\djangoProjects\keep_healthy\diabetes\views.py", line 29, in fetch_diabetes_data
    user = fetch_user_info(request).user
AttributeError: 'str' object has no attribute 'user'

[ERROR] 2022-04-27 21:57:28,134 log 224 Internal Server Error: /diabetes/fetch_diabetes_data/
Traceback (most recent call last):
  File "D:\Application\Anaconda\envs\ML\lib\site-packages\django\core\handlers\exception.py", line 47, in inner
    response = get_response(request)
  File "D:\Application\Anaconda\envs\ML\lib\site-packages\django\core\handlers\base.py", line 181, in _get_response
    response = wrapped_callback(request, *callback_args, **callback_kwargs)
  File "D:\Application\Anaconda\envs\ML\lib\site-packages\django\views\decorators\csrf.py", line 54, in wrapped_view
    return view_func(*args, **kwargs)
  File "D:\Application\Anaconda\envs\ML\lib\site-packages\rest_framework\viewsets.py", line 125, in view
    return self.dispatch(request, *args, **kwargs)
  File "D:\Application\Anaconda\envs\ML\lib\site-packages\rest_framework\views.py", line 511, in dispatch
    self.response = self.finalize_response(request, response, *args, **kwargs)
  File "D:\Application\Anaconda\envs\ML\lib\site-packages\rest_framework\views.py", line 423, in finalize_response
    assert isinstance(response, HttpResponseBase), (
AssertionError: Expected a `Response`, `HttpResponse` or `HttpStreamingResponse` to be returned from the view, but received a `<class 'NoneType'>`
[ERROR] 2022-04-27 21:58:12,100 views 34 Traceback (most recent call last):
  File "E:\Projects\djangoProjects\keep_healthy\diabetes\views.py", line 29, in fetch_diabetes_data
    user = fetch_user_info(request).user
AttributeError: 'str' object has no attribute 'user'

[ERROR] 2022-04-27 21:58:12,381 log 224 Internal Server Error: /diabetes/fetch_diabetes_data/
Traceback (most recent call last):
  File "D:\Application\Anaconda\envs\ML\lib\site-packages\django\core\handlers\exception.py", line 47, in inner
    response = get_response(request)
  File "D:\Application\Anaconda\envs\ML\lib\site-packages\django\core\handlers\base.py", line 181, in _get_response
    response = wrapped_callback(request, *callback_args, **callback_kwargs)
  File "D:\Application\Anaconda\envs\ML\lib\site-packages\django\views\decorators\csrf.py", line 54, in wrapped_view
    return view_func(*args, **kwargs)
  File "D:\Application\Anaconda\envs\ML\lib\site-packages\rest_framework\viewsets.py", line 125, in view
    return self.dispatch(request, *args, **kwargs)
  File "D:\Application\Anaconda\envs\ML\lib\site-packages\rest_framework\views.py", line 511, in dispatch
    self.response = self.finalize_response(request, response, *args, **kwargs)
  File "D:\Application\Anaconda\envs\ML\lib\site-packages\rest_framework\views.py", line 423, in finalize_response
    assert isinstance(response, HttpResponseBase), (
AssertionError: Expected a `Response`, `HttpResponse` or `HttpStreamingResponse` to be returned from the view, but received a `<class 'NoneType'>`
[ERROR] 2022-04-27 22:00:17,845 views 34 Traceback (most recent call last):
  File "E:\Projects\djangoProjects\keep_healthy\diabetes\views.py", line 29, in fetch_diabetes_data
    user = fetch_user_info(request).user
AttributeError: 'str' object has no attribute 'user'

[ERROR] 2022-04-27 22:00:18,095 log 224 Internal Server Error: /diabetes/fetch_diabetes_data/
Traceback (most recent call last):
  File "D:\Application\Anaconda\envs\ML\lib\site-packages\django\core\handlers\exception.py", line 47, in inner
    response = get_response(request)
  File "D:\Application\Anaconda\envs\ML\lib\site-packages\django\core\handlers\base.py", line 181, in _get_response
    response = wrapped_callback(request, *callback_args, **callback_kwargs)
  File "D:\Application\Anaconda\envs\ML\lib\site-packages\django\views\decorators\csrf.py", line 54, in wrapped_view
    return view_func(*args, **kwargs)
  File "D:\Application\Anaconda\envs\ML\lib\site-packages\rest_framework\viewsets.py", line 125, in view
    return self.dispatch(request, *args, **kwargs)
  File "D:\Application\Anaconda\envs\ML\lib\site-packages\rest_framework\views.py", line 511, in dispatch
    self.response = self.finalize_response(request, response, *args, **kwargs)
  File "D:\Application\Anaconda\envs\ML\lib\site-packages\rest_framework\views.py", line 423, in finalize_response
    assert isinstance(response, HttpResponseBase), (
AssertionError: Expected a `Response`, `HttpResponse` or `HttpStreamingResponse` to be returned from the view, but received a `<class 'NoneType'>`
[ERROR] 2022-04-27 22:06:11,461 views 34 Traceback (most recent call last):
  File "E:\Projects\djangoProjects\keep_healthy\diabetes\views.py", line 29, in fetch_diabetes_data
    user = fetch_user_info(request).user
AttributeError: 'str' object has no attribute 'user'

[ERROR] 2022-04-27 22:06:11,766 log 224 Internal Server Error: /diabetes/fetch_diabetes_data/
Traceback (most recent call last):
  File "D:\Application\Anaconda\envs\ML\lib\site-packages\django\core\handlers\exception.py", line 47, in inner
    response = get_response(request)
  File "D:\Application\Anaconda\envs\ML\lib\site-packages\django\core\handlers\base.py", line 181, in _get_response
    response = wrapped_callback(request, *callback_args, **callback_kwargs)
  File "D:\Application\Anaconda\envs\ML\lib\site-packages\django\views\decorators\csrf.py", line 54, in wrapped_view
    return view_func(*args, **kwargs)
  File "D:\Application\Anaconda\envs\ML\lib\site-packages\rest_framework\viewsets.py", line 125, in view
    return self.dispatch(request, *args, **kwargs)
  File "D:\Application\Anaconda\envs\ML\lib\site-packages\rest_framework\views.py", line 511, in dispatch
    self.response = self.finalize_response(request, response, *args, **kwargs)
  File "D:\Application\Anaconda\envs\ML\lib\site-packages\rest_framework\views.py", line 423, in finalize_response
    assert isinstance(response, HttpResponseBase), (
AssertionError: Expected a `Response`, `HttpResponse` or `HttpStreamingResponse` to be returned from the view, but received a `<class 'NoneType'>`
[ERROR] 2022-04-27 22:07:13,640 views 34 Traceback (most recent call last):
  File "E:\Projects\djangoProjects\keep_healthy\diabetes\views.py", line 29, in fetch_diabetes_data
    user = fetch_user_info(request).user
AttributeError: 'dict' object has no attribute 'user'

[ERROR] 2022-04-27 22:07:13,980 log 224 Internal Server Error: /diabetes/fetch_diabetes_data/
Traceback (most recent call last):
  File "D:\Application\Anaconda\envs\ML\lib\site-packages\django\core\handlers\exception.py", line 47, in inner
    response = get_response(request)
  File "D:\Application\Anaconda\envs\ML\lib\site-packages\django\core\handlers\base.py", line 181, in _get_response
    response = wrapped_callback(request, *callback_args, **callback_kwargs)
  File "D:\Application\Anaconda\envs\ML\lib\site-packages\django\views\decorators\csrf.py", line 54, in wrapped_view
    return view_func(*args, **kwargs)
  File "D:\Application\Anaconda\envs\ML\lib\site-packages\rest_framework\viewsets.py", line 125, in view
    return self.dispatch(request, *args, **kwargs)
  File "D:\Application\Anaconda\envs\ML\lib\site-packages\rest_framework\views.py", line 511, in dispatch
    self.response = self.finalize_response(request, response, *args, **kwargs)
  File "D:\Application\Anaconda\envs\ML\lib\site-packages\rest_framework\views.py", line 423, in finalize_response
    assert isinstance(response, HttpResponseBase), (
AssertionError: Expected a `Response`, `HttpResponse` or `HttpStreamingResponse` to be returned from the view, but received a `<class 'NoneType'>`
[ERROR] 2022-04-27 22:08:08,987 log 224 Internal Server Error: /diabetes/fetch_diabetes_data/
Traceback (most recent call last):
  File "D:\Application\Anaconda\envs\ML\lib\site-packages\django\core\handlers\exception.py", line 47, in inner
    response = get_response(request)
  File "D:\Application\Anaconda\envs\ML\lib\site-packages\django\core\handlers\base.py", line 181, in _get_response
    response = wrapped_callback(request, *callback_args, **callback_kwargs)
  File "D:\Application\Anaconda\envs\ML\lib\site-packages\django\views\decorators\csrf.py", line 54, in wrapped_view
    return view_func(*args, **kwargs)
  File "D:\Application\Anaconda\envs\ML\lib\site-packages\rest_framework\viewsets.py", line 125, in view
    return self.dispatch(request, *args, **kwargs)
  File "D:\Application\Anaconda\envs\ML\lib\site-packages\rest_framework\views.py", line 511, in dispatch
    self.response = self.finalize_response(request, response, *args, **kwargs)
  File "D:\Application\Anaconda\envs\ML\lib\site-packages\rest_framework\views.py", line 423, in finalize_response
    assert isinstance(response, HttpResponseBase), (
AssertionError: Expected a `Response`, `HttpResponse` or `HttpStreamingResponse` to be returned from the view, but received a `<class 'NoneType'>`
[ERROR] 2022-04-27 22:09:47,637 log 224 Internal Server Error: /diabetes/fetch_diabetes_data/
Traceback (most recent call last):
  File "D:\Application\Anaconda\envs\ML\lib\site-packages\django\core\handlers\exception.py", line 47, in inner
    response = get_response(request)
  File "D:\Application\Anaconda\envs\ML\lib\site-packages\django\core\handlers\base.py", line 181, in _get_response
    response = wrapped_callback(request, *callback_args, **callback_kwargs)
  File "D:\Application\Anaconda\envs\ML\lib\site-packages\django\views\decorators\csrf.py", line 54, in wrapped_view
    return view_func(*args, **kwargs)
  File "D:\Application\Anaconda\envs\ML\lib\site-packages\rest_framework\viewsets.py", line 125, in view
    return self.dispatch(request, *args, **kwargs)
  File "D:\Application\Anaconda\envs\ML\lib\site-packages\rest_framework\views.py", line 511, in dispatch
    self.response = self.finalize_response(request, response, *args, **kwargs)
  File "D:\Application\Anaconda\envs\ML\lib\site-packages\rest_framework\views.py", line 423, in finalize_response
    assert isinstance(response, HttpResponseBase), (
AssertionError: Expected a `Response`, `HttpResponse` or `HttpStreamingResponse` to be returned from the view, but received a `<class 'NoneType'>`
[ERROR] 2022-04-27 22:10:11,117 log 224 Internal Server Error: /diabetes/fetch_diabetes_data/
Traceback (most recent call last):
  File "D:\Application\Anaconda\envs\ML\lib\site-packages\django\core\handlers\exception.py", line 47, in inner
    response = get_response(request)
  File "D:\Application\Anaconda\envs\ML\lib\site-packages\django\core\handlers\base.py", line 181, in _get_response
    response = wrapped_callback(request, *callback_args, **callback_kwargs)
  File "D:\Application\Anaconda\envs\ML\lib\site-packages\django\views\decorators\csrf.py", line 54, in wrapped_view
    return view_func(*args, **kwargs)
  File "D:\Application\Anaconda\envs\ML\lib\site-packages\rest_framework\viewsets.py", line 125, in view
    return self.dispatch(request, *args, **kwargs)
  File "D:\Application\Anaconda\envs\ML\lib\site-packages\rest_framework\views.py", line 511, in dispatch
    self.response = self.finalize_response(request, response, *args, **kwargs)
  File "D:\Application\Anaconda\envs\ML\lib\site-packages\rest_framework\views.py", line 423, in finalize_response
    assert isinstance(response, HttpResponseBase), (
AssertionError: Expected a `Response`, `HttpResponse` or `HttpStreamingResponse` to be returned from the view, but received a `<class 'NoneType'>`
[ERROR] 2022-04-27 22:17:57,665 views 35 Traceback (most recent call last):
  File "E:\Projects\djangoProjects\keep_healthy\diabetes\views.py", line 31, in fetch_diabetes_data
    print(diabetes[0].values())
AttributeError: 'Diabetes' object has no attribute 'values'

[ERROR] 2022-04-27 22:17:57,943 log 224 Internal Server Error: /diabetes/fetch_diabetes_data/
Traceback (most recent call last):
  File "D:\Application\Anaconda\envs\ML\lib\site-packages\django\core\handlers\exception.py", line 47, in inner
    response = get_response(request)
  File "D:\Application\Anaconda\envs\ML\lib\site-packages\django\core\handlers\base.py", line 181, in _get_response
    response = wrapped_callback(request, *callback_args, **callback_kwargs)
  File "D:\Application\Anaconda\envs\ML\lib\site-packages\django\views\decorators\csrf.py", line 54, in wrapped_view
    return view_func(*args, **kwargs)
  File "D:\Application\Anaconda\envs\ML\lib\site-packages\rest_framework\viewsets.py", line 125, in view
    return self.dispatch(request, *args, **kwargs)
  File "D:\Application\Anaconda\envs\ML\lib\site-packages\rest_framework\views.py", line 511, in dispatch
    self.response = self.finalize_response(request, response, *args, **kwargs)
  File "D:\Application\Anaconda\envs\ML\lib\site-packages\rest_framework\views.py", line 423, in finalize_response
    assert isinstance(response, HttpResponseBase), (
AssertionError: Expected a `Response`, `HttpResponse` or `HttpStreamingResponse` to be returned from the view, but received a `<class 'NoneType'>`
[ERROR] 2022-04-27 22:18:30,266 log 224 Internal Server Error: /diabetes/fetch_diabetes_data/
Traceback (most recent call last):
  File "D:\Application\Anaconda\envs\ML\lib\site-packages\django\core\handlers\exception.py", line 47, in inner
    response = get_response(request)
  File "D:\Application\Anaconda\envs\ML\lib\site-packages\django\core\handlers\base.py", line 181, in _get_response
    response = wrapped_callback(request, *callback_args, **callback_kwargs)
  File "D:\Application\Anaconda\envs\ML\lib\site-packages\django\views\decorators\csrf.py", line 54, in wrapped_view
    return view_func(*args, **kwargs)
  File "D:\Application\Anaconda\envs\ML\lib\site-packages\rest_framework\viewsets.py", line 125, in view
    return self.dispatch(request, *args, **kwargs)
  File "D:\Application\Anaconda\envs\ML\lib\site-packages\rest_framework\views.py", line 511, in dispatch
    self.response = self.finalize_response(request, response, *args, **kwargs)
  File "D:\Application\Anaconda\envs\ML\lib\site-packages\rest_framework\views.py", line 423, in finalize_response
    assert isinstance(response, HttpResponseBase), (
AssertionError: Expected a `Response`, `HttpResponse` or `HttpStreamingResponse` to be returned from the view, but received a `<class 'NoneType'>`
[ERROR] 2022-04-27 22:21:44,305 log 224 Internal Server Error: /diabetes/fetch_diabetes_data/
Traceback (most recent call last):
  File "D:\Application\Anaconda\envs\ML\lib\site-packages\django\core\handlers\exception.py", line 47, in inner
    response = get_response(request)
  File "D:\Application\Anaconda\envs\ML\lib\site-packages\django\core\handlers\base.py", line 181, in _get_response
    response = wrapped_callback(request, *callback_args, **callback_kwargs)
  File "D:\Application\Anaconda\envs\ML\lib\site-packages\django\views\decorators\csrf.py", line 54, in wrapped_view
    return view_func(*args, **kwargs)
  File "D:\Application\Anaconda\envs\ML\lib\site-packages\rest_framework\viewsets.py", line 125, in view
    return self.dispatch(request, *args, **kwargs)
  File "D:\Application\Anaconda\envs\ML\lib\site-packages\rest_framework\views.py", line 511, in dispatch
    self.response = self.finalize_response(request, response, *args, **kwargs)
  File "D:\Application\Anaconda\envs\ML\lib\site-packages\rest_framework\views.py", line 423, in finalize_response
    assert isinstance(response, HttpResponseBase), (
AssertionError: Expected a `Response`, `HttpResponse` or `HttpStreamingResponse` to be returned from the view, but received a `<class 'NoneType'>`
[ERROR] 2022-04-27 22:23:31,661 views 35 Traceback (most recent call last):
  File "E:\Projects\djangoProjects\keep_healthy\diabetes\views.py", line 30, in fetch_diabetes_data
    diabetes = Diabetes.objects.filter(User=1, is_active=True)
  File "D:\Application\Anaconda\envs\ML\lib\site-packages\django\db\models\manager.py", line 85, in manager_method
    return getattr(self.get_queryset(), name)(*args, **kwargs)
  File "D:\Application\Anaconda\envs\ML\lib\site-packages\django\db\models\query.py", line 941, in filter
    return self._filter_or_exclude(False, args, kwargs)
django.core.exceptions.FieldError: Cannot resolve keyword 'User' into field. Choices are: age, blood_pressure, bmi, create_time, glucose, id, insulin, is_active, outcome, pedigree_function, pregnancies, skin_thickness, update_time, user, user_id

[ERROR] 2022-04-27 22:23:31,931 log 224 Internal Server Error: /diabetes/fetch_diabetes_data/
Traceback (most recent call last):
  File "D:\Application\Anaconda\envs\ML\lib\site-packages\django\core\handlers\exception.py", line 47, in inner
    response = get_response(request)
  File "D:\Application\Anaconda\envs\ML\lib\site-packages\django\core\handlers\base.py", line 181, in _get_response
    response = wrapped_callback(request, *callback_args, **callback_kwargs)
  File "D:\Application\Anaconda\envs\ML\lib\site-packages\django\views\decorators\csrf.py", line 54, in wrapped_view
    return view_func(*args, **kwargs)
  File "D:\Application\Anaconda\envs\ML\lib\site-packages\rest_framework\viewsets.py", line 125, in view
    return self.dispatch(request, *args, **kwargs)
  File "D:\Application\Anaconda\envs\ML\lib\site-packages\rest_framework\views.py", line 511, in dispatch
    self.response = self.finalize_response(request, response, *args, **kwargs)
  File "D:\Application\Anaconda\envs\ML\lib\site-packages\rest_framework\views.py", line 423, in finalize_response
    assert isinstance(response, HttpResponseBase), (
AssertionError: Expected a `Response`, `HttpResponse` or `HttpStreamingResponse` to be returned from the view, but received a `<class 'NoneType'>`
[ERROR] 2022-04-27 22:24:26,183 log 224 Internal Server Error: /diabetes/fetch_diabetes_data/
Traceback (most recent call last):
  File "D:\Application\Anaconda\envs\ML\lib\site-packages\django\core\handlers\exception.py", line 47, in inner
    response = get_response(request)
  File "D:\Application\Anaconda\envs\ML\lib\site-packages\django\core\handlers\base.py", line 181, in _get_response
    response = wrapped_callback(request, *callback_args, **callback_kwargs)
  File "D:\Application\Anaconda\envs\ML\lib\site-packages\django\views\decorators\csrf.py", line 54, in wrapped_view
    return view_func(*args, **kwargs)
  File "D:\Application\Anaconda\envs\ML\lib\site-packages\rest_framework\viewsets.py", line 125, in view
    return self.dispatch(request, *args, **kwargs)
  File "D:\Application\Anaconda\envs\ML\lib\site-packages\rest_framework\views.py", line 511, in dispatch
    self.response = self.finalize_response(request, response, *args, **kwargs)
  File "D:\Application\Anaconda\envs\ML\lib\site-packages\rest_framework\views.py", line 423, in finalize_response
    assert isinstance(response, HttpResponseBase), (
AssertionError: Expected a `Response`, `HttpResponse` or `HttpStreamingResponse` to be returned from the view, but received a `<class 'NoneType'>`
[ERROR] 2022-04-27 22:25:07,536 log 224 Internal Server Error: /diabetes/fetch_diabetes_data/
Traceback (most recent call last):
  File "D:\Application\Anaconda\envs\ML\lib\site-packages\django\core\handlers\exception.py", line 47, in inner
    response = get_response(request)
  File "D:\Application\Anaconda\envs\ML\lib\site-packages\django\core\handlers\base.py", line 181, in _get_response
    response = wrapped_callback(request, *callback_args, **callback_kwargs)
  File "D:\Application\Anaconda\envs\ML\lib\site-packages\django\views\decorators\csrf.py", line 54, in wrapped_view
    return view_func(*args, **kwargs)
  File "D:\Application\Anaconda\envs\ML\lib\site-packages\rest_framework\viewsets.py", line 125, in view
    return self.dispatch(request, *args, **kwargs)
  File "D:\Application\Anaconda\envs\ML\lib\site-packages\rest_framework\views.py", line 511, in dispatch
    self.response = self.finalize_response(request, response, *args, **kwargs)
  File "D:\Application\Anaconda\envs\ML\lib\site-packages\rest_framework\views.py", line 423, in finalize_response
    assert isinstance(response, HttpResponseBase), (
AssertionError: Expected a `Response`, `HttpResponse` or `HttpStreamingResponse` to be returned from the view, but received a `<class 'NoneType'>`
[ERROR] 2022-04-28 07:38:31,253 log 224 Internal Server Error: /diabetes/fetch_diabetes_data/
Traceback (most recent call last):
  File "D:\Application\Anaconda\envs\ML\lib\site-packages\django\core\handlers\exception.py", line 47, in inner
    response = get_response(request)
  File "D:\Application\Anaconda\envs\ML\lib\site-packages\django\core\handlers\base.py", line 181, in _get_response
    response = wrapped_callback(request, *callback_args, **callback_kwargs)
  File "D:\Application\Anaconda\envs\ML\lib\site-packages\django\views\decorators\csrf.py", line 54, in wrapped_view
    return view_func(*args, **kwargs)
  File "D:\Application\Anaconda\envs\ML\lib\site-packages\rest_framework\viewsets.py", line 125, in view
    return self.dispatch(request, *args, **kwargs)
  File "D:\Application\Anaconda\envs\ML\lib\site-packages\rest_framework\views.py", line 511, in dispatch
    self.response = self.finalize_response(request, response, *args, **kwargs)
  File "D:\Application\Anaconda\envs\ML\lib\site-packages\rest_framework\views.py", line 423, in finalize_response
    assert isinstance(response, HttpResponseBase), (
AssertionError: Expected a `Response`, `HttpResponse` or `HttpStreamingResponse` to be returned from the view, but received a `<class 'NoneType'>`
[ERROR] 2022-04-28 07:40:58,505 log 224 Internal Server Error: /diabetes/fetch_diabetes_data/
Traceback (most recent call last):
  File "D:\Application\Anaconda\envs\ML\lib\site-packages\django\core\handlers\exception.py", line 47, in inner
    response = get_response(request)
  File "D:\Application\Anaconda\envs\ML\lib\site-packages\django\core\handlers\base.py", line 181, in _get_response
    response = wrapped_callback(request, *callback_args, **callback_kwargs)
  File "D:\Application\Anaconda\envs\ML\lib\site-packages\django\views\decorators\csrf.py", line 54, in wrapped_view
    return view_func(*args, **kwargs)
  File "D:\Application\Anaconda\envs\ML\lib\site-packages\rest_framework\viewsets.py", line 125, in view
    return self.dispatch(request, *args, **kwargs)
  File "D:\Application\Anaconda\envs\ML\lib\site-packages\rest_framework\views.py", line 511, in dispatch
    self.response = self.finalize_response(request, response, *args, **kwargs)
  File "D:\Application\Anaconda\envs\ML\lib\site-packages\rest_framework\views.py", line 423, in finalize_response
    assert isinstance(response, HttpResponseBase), (
AssertionError: Expected a `Response`, `HttpResponse` or `HttpStreamingResponse` to be returned from the view, but received a `<class 'NoneType'>`
[ERROR] 2022-04-28 07:50:46,834 log 224 Internal Server Error: /diabetes/fetch_diabetes_data/
Traceback (most recent call last):
  File "D:\Application\Anaconda\envs\ML\lib\site-packages\django\core\handlers\exception.py", line 47, in inner
    response = get_response(request)
  File "D:\Application\Anaconda\envs\ML\lib\site-packages\django\core\handlers\base.py", line 181, in _get_response
    response = wrapped_callback(request, *callback_args, **callback_kwargs)
  File "D:\Application\Anaconda\envs\ML\lib\site-packages\django\views\decorators\csrf.py", line 54, in wrapped_view
    return view_func(*args, **kwargs)
  File "D:\Application\Anaconda\envs\ML\lib\site-packages\rest_framework\viewsets.py", line 125, in view
    return self.dispatch(request, *args, **kwargs)
  File "D:\Application\Anaconda\envs\ML\lib\site-packages\rest_framework\views.py", line 511, in dispatch
    self.response = self.finalize_response(request, response, *args, **kwargs)
  File "D:\Application\Anaconda\envs\ML\lib\site-packages\rest_framework\views.py", line 423, in finalize_response
    assert isinstance(response, HttpResponseBase), (
AssertionError: Expected a `Response`, `HttpResponse` or `HttpStreamingResponse` to be returned from the view, but received a `<class 'NoneType'>`
[ERROR] 2022-04-28 07:51:24,971 log 224 Internal Server Error: /diabetes/fetch_diabetes_data/
Traceback (most recent call last):
  File "D:\Application\Anaconda\envs\ML\lib\site-packages\django\core\handlers\exception.py", line 47, in inner
    response = get_response(request)
  File "D:\Application\Anaconda\envs\ML\lib\site-packages\django\core\handlers\base.py", line 181, in _get_response
    response = wrapped_callback(request, *callback_args, **callback_kwargs)
  File "D:\Application\Anaconda\envs\ML\lib\site-packages\django\views\decorators\csrf.py", line 54, in wrapped_view
    return view_func(*args, **kwargs)
  File "D:\Application\Anaconda\envs\ML\lib\site-packages\rest_framework\viewsets.py", line 125, in view
    return self.dispatch(request, *args, **kwargs)
  File "D:\Application\Anaconda\envs\ML\lib\site-packages\rest_framework\views.py", line 511, in dispatch
    self.response = self.finalize_response(request, response, *args, **kwargs)
  File "D:\Application\Anaconda\envs\ML\lib\site-packages\rest_framework\views.py", line 423, in finalize_response
    assert isinstance(response, HttpResponseBase), (
AssertionError: Expected a `Response`, `HttpResponse` or `HttpStreamingResponse` to be returned from the view, but received a `<class 'NoneType'>`
[ERROR] 2022-04-28 08:46:54,188 log 224 Internal Server Error: /diabetes/fetch_diabetes_data/
Traceback (most recent call last):
  File "D:\Application\Anaconda\envs\ML\lib\site-packages\django\core\handlers\exception.py", line 47, in inner
    response = get_response(request)
  File "D:\Application\Anaconda\envs\ML\lib\site-packages\django\core\handlers\base.py", line 181, in _get_response
    response = wrapped_callback(request, *callback_args, **callback_kwargs)
  File "D:\Application\Anaconda\envs\ML\lib\site-packages\django\views\decorators\csrf.py", line 54, in wrapped_view
    return view_func(*args, **kwargs)
  File "D:\Application\Anaconda\envs\ML\lib\site-packages\rest_framework\viewsets.py", line 125, in view
    return self.dispatch(request, *args, **kwargs)
  File "D:\Application\Anaconda\envs\ML\lib\site-packages\rest_framework\views.py", line 511, in dispatch
    self.response = self.finalize_response(request, response, *args, **kwargs)
  File "D:\Application\Anaconda\envs\ML\lib\site-packages\rest_framework\views.py", line 423, in finalize_response
    assert isinstance(response, HttpResponseBase), (
AssertionError: Expected a `Response`, `HttpResponse` or `HttpStreamingResponse` to be returned from the view, but received a `<class 'NoneType'>`
[ERROR] 2022-04-28 08:47:53,524 log 224 Internal Server Error: /diabetes/fetch_diabetes_data/
Traceback (most recent call last):
  File "D:\Application\Anaconda\envs\ML\lib\site-packages\django\core\handlers\exception.py", line 47, in inner
    response = get_response(request)
  File "D:\Application\Anaconda\envs\ML\lib\site-packages\django\core\handlers\base.py", line 181, in _get_response
    response = wrapped_callback(request, *callback_args, **callback_kwargs)
  File "D:\Application\Anaconda\envs\ML\lib\site-packages\django\views\decorators\csrf.py", line 54, in wrapped_view
    return view_func(*args, **kwargs)
  File "D:\Application\Anaconda\envs\ML\lib\site-packages\rest_framework\viewsets.py", line 125, in view
    return self.dispatch(request, *args, **kwargs)
  File "D:\Application\Anaconda\envs\ML\lib\site-packages\rest_framework\views.py", line 511, in dispatch
    self.response = self.finalize_response(request, response, *args, **kwargs)
  File "D:\Application\Anaconda\envs\ML\lib\site-packages\rest_framework\views.py", line 423, in finalize_response
    assert isinstance(response, HttpResponseBase), (
AssertionError: Expected a `Response`, `HttpResponse` or `HttpStreamingResponse` to be returned from the view, but received a `<class 'NoneType'>`
[ERROR] 2022-04-28 08:48:26,051 log 224 Internal Server Error: /diabetes/fetch_diabetes_data/
Traceback (most recent call last):
  File "D:\Application\Anaconda\envs\ML\lib\site-packages\django\core\handlers\exception.py", line 47, in inner
    response = get_response(request)
  File "D:\Application\Anaconda\envs\ML\lib\site-packages\django\core\handlers\base.py", line 181, in _get_response
    response = wrapped_callback(request, *callback_args, **callback_kwargs)
  File "D:\Application\Anaconda\envs\ML\lib\site-packages\django\views\decorators\csrf.py", line 54, in wrapped_view
    return view_func(*args, **kwargs)
  File "D:\Application\Anaconda\envs\ML\lib\site-packages\rest_framework\viewsets.py", line 125, in view
    return self.dispatch(request, *args, **kwargs)
  File "D:\Application\Anaconda\envs\ML\lib\site-packages\rest_framework\views.py", line 511, in dispatch
    self.response = self.finalize_response(request, response, *args, **kwargs)
  File "D:\Application\Anaconda\envs\ML\lib\site-packages\rest_framework\views.py", line 423, in finalize_response
    assert isinstance(response, HttpResponseBase), (
AssertionError: Expected a `Response`, `HttpResponse` or `HttpStreamingResponse` to be returned from the view, but received a `<class 'NoneType'>`
[ERROR] 2022-04-28 08:53:28,965 views 58 Traceback (most recent call last):
  File "D:\Application\Anaconda\envs\ML\lib\site-packages\rest_framework\parsers.py", line 65, in parse
    return json.load(decoded_stream, parse_constant=parse_constant)
  File "D:\Application\Anaconda\envs\ML\lib\site-packages\rest_framework\utils\json.py", line 31, in load
    return json.load(*args, **kwargs)
  File "D:\Application\Anaconda\envs\ML\lib\json\__init__.py", line 293, in load
    return loads(fp.read(),
json.decoder.JSONDecodeError: Expecting value: line 1 column 1 (char 0)

During handling of the above exception, another exception occurred:

Traceback (most recent call last):
  File "E:\Projects\djangoProjects\keep_healthy\users\views.py", line 36, in login
    username = request.data.get('username')
  File "D:\Application\Anaconda\envs\ML\lib\site-packages\rest_framework\request.py", line 216, in data
    self._load_data_and_files()
  File "D:\Application\Anaconda\envs\ML\lib\site-packages\rest_framework\request.py", line 279, in _load_data_and_files
    self._data, self._files = self._parse()
rest_framework.exceptions.ParseError: JSON parse error - Expecting value: line 1 column 1 (char 0)

[ERROR] 2022-04-28 08:53:52,171 views 58 Traceback (most recent call last):
  File "D:\Application\Anaconda\envs\ML\lib\site-packages\rest_framework\parsers.py", line 65, in parse
    return json.load(decoded_stream, parse_constant=parse_constant)
  File "D:\Application\Anaconda\envs\ML\lib\site-packages\rest_framework\utils\json.py", line 31, in load
    return json.load(*args, **kwargs)
  File "D:\Application\Anaconda\envs\ML\lib\json\__init__.py", line 293, in load
    return loads(fp.read(),
json.decoder.JSONDecodeError: Expecting value: line 1 column 1 (char 0)

During handling of the above exception, another exception occurred:

Traceback (most recent call last):
  File "E:\Projects\djangoProjects\keep_healthy\users\views.py", line 36, in login
    username = request.data.get('username')
  File "D:\Application\Anaconda\envs\ML\lib\site-packages\rest_framework\request.py", line 216, in data
    self._load_data_and_files()
  File "D:\Application\Anaconda\envs\ML\lib\site-packages\rest_framework\request.py", line 279, in _load_data_and_files
    self._data, self._files = self._parse()
rest_framework.exceptions.ParseError: JSON parse error - Expecting value: line 1 column 1 (char 0)

[ERROR] 2022-04-28 08:55:22,905 views 58 Traceback (most recent call last):
  File "D:\Application\Anaconda\envs\ML\lib\site-packages\rest_framework\parsers.py", line 65, in parse
    return json.load(decoded_stream, parse_constant=parse_constant)
  File "D:\Application\Anaconda\envs\ML\lib\site-packages\rest_framework\utils\json.py", line 31, in load
    return json.load(*args, **kwargs)
  File "D:\Application\Anaconda\envs\ML\lib\json\__init__.py", line 293, in load
    return loads(fp.read(),
json.decoder.JSONDecodeError: Expecting value: line 1 column 1 (char 0)

During handling of the above exception, another exception occurred:

Traceback (most recent call last):
  File "E:\Projects\djangoProjects\keep_healthy\users\views.py", line 36, in login
    username = request.data.get('username')
  File "D:\Application\Anaconda\envs\ML\lib\site-packages\rest_framework\request.py", line 216, in data
    self._load_data_and_files()
  File "D:\Application\Anaconda\envs\ML\lib\site-packages\rest_framework\request.py", line 279, in _load_data_and_files
    self._data, self._files = self._parse()
rest_framework.exceptions.ParseError: JSON parse error - Expecting value: line 1 column 1 (char 0)

[ERROR] 2022-04-28 09:01:43,538 views 58 Traceback (most recent call last):
  File "D:\Application\Anaconda\envs\ML\lib\site-packages\rest_framework\parsers.py", line 65, in parse
    return json.load(decoded_stream, parse_constant=parse_constant)
  File "D:\Application\Anaconda\envs\ML\lib\site-packages\rest_framework\utils\json.py", line 31, in load
    return json.load(*args, **kwargs)
  File "D:\Application\Anaconda\envs\ML\lib\json\__init__.py", line 293, in load
    return loads(fp.read(),
json.decoder.JSONDecodeError: Expecting value: line 1 column 1 (char 0)

During handling of the above exception, another exception occurred:

Traceback (most recent call last):
  File "E:\Projects\djangoProjects\keep_healthy\users\views.py", line 36, in login
    username = request.data.get('username')
  File "D:\Application\Anaconda\envs\ML\lib\site-packages\rest_framework\request.py", line 216, in data
    self._load_data_and_files()
  File "D:\Application\Anaconda\envs\ML\lib\site-packages\rest_framework\request.py", line 279, in _load_data_and_files
    self._data, self._files = self._parse()
rest_framework.exceptions.ParseError: JSON parse error - Expecting value: line 1 column 1 (char 0)

[ERROR] 2022-04-28 09:02:49,098 views 58 Traceback (most recent call last):
  File "D:\Application\Anaconda\envs\ML\lib\site-packages\rest_framework\parsers.py", line 65, in parse
    return json.load(decoded_stream, parse_constant=parse_constant)
  File "D:\Application\Anaconda\envs\ML\lib\site-packages\rest_framework\utils\json.py", line 31, in load
    return json.load(*args, **kwargs)
  File "D:\Application\Anaconda\envs\ML\lib\json\__init__.py", line 293, in load
    return loads(fp.read(),
json.decoder.JSONDecodeError: Expecting value: line 1 column 1 (char 0)

During handling of the above exception, another exception occurred:

Traceback (most recent call last):
  File "E:\Projects\djangoProjects\keep_healthy\users\views.py", line 36, in login
    username = request.data.get('username')
  File "D:\Application\Anaconda\envs\ML\lib\site-packages\rest_framework\request.py", line 216, in data
    self._load_data_and_files()
  File "D:\Application\Anaconda\envs\ML\lib\site-packages\rest_framework\request.py", line 279, in _load_data_and_files
    self._data, self._files = self._parse()
rest_framework.exceptions.ParseError: JSON parse error - Expecting value: line 1 column 1 (char 0)

[ERROR] 2022-04-28 09:07:38,292 views 58 Traceback (most recent call last):
  File "D:\Application\Anaconda\envs\ML\lib\site-packages\rest_framework\parsers.py", line 65, in parse
    return json.load(decoded_stream, parse_constant=parse_constant)
  File "D:\Application\Anaconda\envs\ML\lib\site-packages\rest_framework\utils\json.py", line 31, in load
    return json.load(*args, **kwargs)
  File "D:\Application\Anaconda\envs\ML\lib\json\__init__.py", line 293, in load
    return loads(fp.read(),
json.decoder.JSONDecodeError: Expecting value: line 1 column 1 (char 0)

During handling of the above exception, another exception occurred:

Traceback (most recent call last):
  File "E:\Projects\djangoProjects\keep_healthy\users\views.py", line 36, in login
    username = request.data.get('username')
  File "D:\Application\Anaconda\envs\ML\lib\site-packages\rest_framework\request.py", line 216, in data
    self._load_data_and_files()
  File "D:\Application\Anaconda\envs\ML\lib\site-packages\rest_framework\request.py", line 279, in _load_data_and_files
    self._data, self._files = self._parse()
rest_framework.exceptions.ParseError: JSON parse error - Expecting value: line 1 column 1 (char 0)

[ERROR] 2022-04-28 09:10:02,462 views 58 Traceback (most recent call last):
  File "D:\Application\Anaconda\envs\ML\lib\site-packages\rest_framework\parsers.py", line 65, in parse
    return json.load(decoded_stream, parse_constant=parse_constant)
  File "D:\Application\Anaconda\envs\ML\lib\site-packages\rest_framework\utils\json.py", line 31, in load
    return json.load(*args, **kwargs)
  File "D:\Application\Anaconda\envs\ML\lib\json\__init__.py", line 293, in load
    return loads(fp.read(),
json.decoder.JSONDecodeError: Expecting value: line 1 column 1 (char 0)

During handling of the above exception, another exception occurred:

Traceback (most recent call last):
  File "E:\Projects\djangoProjects\keep_healthy\users\views.py", line 36, in login
    username = request.data.get('username')
  File "D:\Application\Anaconda\envs\ML\lib\site-packages\rest_framework\request.py", line 216, in data
    self._load_data_and_files()
  File "D:\Application\Anaconda\envs\ML\lib\site-packages\rest_framework\request.py", line 279, in _load_data_and_files
    self._data, self._files = self._parse()
rest_framework.exceptions.ParseError: JSON parse error - Expecting value: line 1 column 1 (char 0)

[ERROR] 2022-04-28 09:11:01,297 views 58 Traceback (most recent call last):
  File "D:\Application\Anaconda\envs\ML\lib\site-packages\rest_framework\parsers.py", line 65, in parse
    return json.load(decoded_stream, parse_constant=parse_constant)
  File "D:\Application\Anaconda\envs\ML\lib\site-packages\rest_framework\utils\json.py", line 31, in load
    return json.load(*args, **kwargs)
  File "D:\Application\Anaconda\envs\ML\lib\json\__init__.py", line 293, in load
    return loads(fp.read(),
json.decoder.JSONDecodeError: Expecting value: line 1 column 1 (char 0)

During handling of the above exception, another exception occurred:

Traceback (most recent call last):
  File "E:\Projects\djangoProjects\keep_healthy\users\views.py", line 36, in login
    username = request.POST.get('username')
  File "D:\Application\Anaconda\envs\ML\lib\site-packages\rest_framework\request.py", line 431, in POST
    self._load_data_and_files()
  File "D:\Application\Anaconda\envs\ML\lib\site-packages\rest_framework\request.py", line 279, in _load_data_and_files
    self._data, self._files = self._parse()
rest_framework.exceptions.ParseError: JSON parse error - Expecting value: line 1 column 1 (char 0)

[ERROR] 2022-04-28 09:11:52,833 views 58 Traceback (most recent call last):
  File "D:\Application\Anaconda\envs\ML\lib\site-packages\rest_framework\parsers.py", line 65, in parse
    return json.load(decoded_stream, parse_constant=parse_constant)
  File "D:\Application\Anaconda\envs\ML\lib\site-packages\rest_framework\utils\json.py", line 31, in load
    return json.load(*args, **kwargs)
  File "D:\Application\Anaconda\envs\ML\lib\json\__init__.py", line 293, in load
    return loads(fp.read(),
json.decoder.JSONDecodeError: Expecting value: line 1 column 1 (char 0)

During handling of the above exception, another exception occurred:

Traceback (most recent call last):
  File "E:\Projects\djangoProjects\keep_healthy\users\views.py", line 36, in login
    username = request.POST.get('username')
  File "D:\Application\Anaconda\envs\ML\lib\site-packages\rest_framework\request.py", line 431, in POST
    self._load_data_and_files()
  File "D:\Application\Anaconda\envs\ML\lib\site-packages\rest_framework\request.py", line 279, in _load_data_and_files
    self._data, self._files = self._parse()
rest_framework.exceptions.ParseError: JSON parse error - Expecting value: line 1 column 1 (char 0)

[ERROR] 2022-04-28 09:13:03,907 views 58 Traceback (most recent call last):
  File "D:\Application\Anaconda\envs\ML\lib\site-packages\rest_framework\parsers.py", line 65, in parse
    return json.load(decoded_stream, parse_constant=parse_constant)
  File "D:\Application\Anaconda\envs\ML\lib\site-packages\rest_framework\utils\json.py", line 31, in load
    return json.load(*args, **kwargs)
  File "D:\Application\Anaconda\envs\ML\lib\json\__init__.py", line 293, in load
    return loads(fp.read(),
json.decoder.JSONDecodeError: Expecting value: line 1 column 1 (char 0)

During handling of the above exception, another exception occurred:

Traceback (most recent call last):
  File "E:\Projects\djangoProjects\keep_healthy\users\views.py", line 36, in login
    username = request.POST.get('username')
  File "D:\Application\Anaconda\envs\ML\lib\site-packages\rest_framework\request.py", line 431, in POST
    self._load_data_and_files()
  File "D:\Application\Anaconda\envs\ML\lib\site-packages\rest_framework\request.py", line 279, in _load_data_and_files
    self._data, self._files = self._parse()
rest_framework.exceptions.ParseError: JSON parse error - Expecting value: line 1 column 1 (char 0)

[ERROR] 2022-04-28 09:14:49,692 views 41 用户None登录异常
[ERROR] 2022-04-28 09:28:11,117 log 224 Internal Server Error: /diabetes/fetch_diabetes_data/
Traceback (most recent call last):
  File "D:\Application\Anaconda\envs\ML\lib\site-packages\django\core\handlers\exception.py", line 47, in inner
    response = get_response(request)
  File "D:\Application\Anaconda\envs\ML\lib\site-packages\django\core\handlers\base.py", line 181, in _get_response
    response = wrapped_callback(request, *callback_args, **callback_kwargs)
  File "D:\Application\Anaconda\envs\ML\lib\site-packages\django\views\decorators\csrf.py", line 54, in wrapped_view
    return view_func(*args, **kwargs)
  File "D:\Application\Anaconda\envs\ML\lib\site-packages\rest_framework\viewsets.py", line 125, in view
    return self.dispatch(request, *args, **kwargs)
  File "D:\Application\Anaconda\envs\ML\lib\site-packages\rest_framework\views.py", line 511, in dispatch
    self.response = self.finalize_response(request, response, *args, **kwargs)
  File "D:\Application\Anaconda\envs\ML\lib\site-packages\rest_framework\views.py", line 423, in finalize_response
    assert isinstance(response, HttpResponseBase), (
AssertionError: Expected a `Response`, `HttpResponse` or `HttpStreamingResponse` to be returned from the view, but received a `<class 'NoneType'>`
[ERROR] 2022-04-28 09:30:46,755 log 224 Internal Server Error: /diabetes/fetch_diabetes_data/
Traceback (most recent call last):
  File "D:\Application\Anaconda\envs\ML\lib\site-packages\django\core\handlers\exception.py", line 47, in inner
    response = get_response(request)
  File "D:\Application\Anaconda\envs\ML\lib\site-packages\django\core\handlers\base.py", line 181, in _get_response
    response = wrapped_callback(request, *callback_args, **callback_kwargs)
  File "D:\Application\Anaconda\envs\ML\lib\site-packages\django\views\decorators\csrf.py", line 54, in wrapped_view
    return view_func(*args, **kwargs)
  File "D:\Application\Anaconda\envs\ML\lib\site-packages\rest_framework\viewsets.py", line 125, in view
    return self.dispatch(request, *args, **kwargs)
  File "D:\Application\Anaconda\envs\ML\lib\site-packages\rest_framework\views.py", line 511, in dispatch
    self.response = self.finalize_response(request, response, *args, **kwargs)
  File "D:\Application\Anaconda\envs\ML\lib\site-packages\rest_framework\views.py", line 423, in finalize_response
    assert isinstance(response, HttpResponseBase), (
AssertionError: Expected a `Response`, `HttpResponse` or `HttpStreamingResponse` to be returned from the view, but received a `<class 'NoneType'>`
[ERROR] 2022-04-28 09:34:14,496 log 224 Internal Server Error: /diabetes/fetch_diabetes_data/
Traceback (most recent call last):
  File "D:\Application\Anaconda\envs\ML\lib\site-packages\django\core\handlers\exception.py", line 47, in inner
    response = get_response(request)
  File "D:\Application\Anaconda\envs\ML\lib\site-packages\django\core\handlers\base.py", line 181, in _get_response
    response = wrapped_callback(request, *callback_args, **callback_kwargs)
  File "D:\Application\Anaconda\envs\ML\lib\site-packages\django\views\decorators\csrf.py", line 54, in wrapped_view
    return view_func(*args, **kwargs)
  File "D:\Application\Anaconda\envs\ML\lib\site-packages\rest_framework\viewsets.py", line 125, in view
    return self.dispatch(request, *args, **kwargs)
  File "D:\Application\Anaconda\envs\ML\lib\site-packages\rest_framework\views.py", line 511, in dispatch
    self.response = self.finalize_response(request, response, *args, **kwargs)
  File "D:\Application\Anaconda\envs\ML\lib\site-packages\rest_framework\views.py", line 423, in finalize_response
    assert isinstance(response, HttpResponseBase), (
AssertionError: Expected a `Response`, `HttpResponse` or `HttpStreamingResponse` to be returned from the view, but received a `<class 'NoneType'>`
[ERROR] 2022-04-28 09:34:41,016 log 224 Internal Server Error: /diabetes/fetch_diabetes_data/
Traceback (most recent call last):
  File "D:\Application\Anaconda\envs\ML\lib\site-packages\django\core\handlers\exception.py", line 47, in inner
    response = get_response(request)
  File "D:\Application\Anaconda\envs\ML\lib\site-packages\django\core\handlers\base.py", line 181, in _get_response
    response = wrapped_callback(request, *callback_args, **callback_kwargs)
  File "D:\Application\Anaconda\envs\ML\lib\site-packages\django\views\decorators\csrf.py", line 54, in wrapped_view
    return view_func(*args, **kwargs)
  File "D:\Application\Anaconda\envs\ML\lib\site-packages\rest_framework\viewsets.py", line 125, in view
    return self.dispatch(request, *args, **kwargs)
  File "D:\Application\Anaconda\envs\ML\lib\site-packages\rest_framework\views.py", line 511, in dispatch
    self.response = self.finalize_response(request, response, *args, **kwargs)
  File "D:\Application\Anaconda\envs\ML\lib\site-packages\rest_framework\views.py", line 423, in finalize_response
    assert isinstance(response, HttpResponseBase), (
AssertionError: Expected a `Response`, `HttpResponse` or `HttpStreamingResponse` to be returned from the view, but received a `<class 'NoneType'>`
[ERROR] 2022-04-28 09:34:52,642 log 224 Internal Server Error: /diabetes/fetch_diabetes_data/
Traceback (most recent call last):
  File "D:\Application\Anaconda\envs\ML\lib\site-packages\django\core\handlers\exception.py", line 47, in inner
    response = get_response(request)
  File "D:\Application\Anaconda\envs\ML\lib\site-packages\django\core\handlers\base.py", line 181, in _get_response
    response = wrapped_callback(request, *callback_args, **callback_kwargs)
  File "D:\Application\Anaconda\envs\ML\lib\site-packages\django\views\decorators\csrf.py", line 54, in wrapped_view
    return view_func(*args, **kwargs)
  File "D:\Application\Anaconda\envs\ML\lib\site-packages\rest_framework\viewsets.py", line 125, in view
    return self.dispatch(request, *args, **kwargs)
  File "D:\Application\Anaconda\envs\ML\lib\site-packages\rest_framework\views.py", line 511, in dispatch
    self.response = self.finalize_response(request, response, *args, **kwargs)
  File "D:\Application\Anaconda\envs\ML\lib\site-packages\rest_framework\views.py", line 423, in finalize_response
    assert isinstance(response, HttpResponseBase), (
AssertionError: Expected a `Response`, `HttpResponse` or `HttpStreamingResponse` to be returned from the view, but received a `<class 'NoneType'>`
[ERROR] 2022-04-28 09:47:05,659 log 224 Internal Server Error: /diabetes/fetch_diabetes_data/
Traceback (most recent call last):
  File "D:\Application\Anaconda\envs\ML\lib\site-packages\django\core\handlers\exception.py", line 47, in inner
    response = get_response(request)
  File "D:\Application\Anaconda\envs\ML\lib\site-packages\django\core\handlers\base.py", line 181, in _get_response
    response = wrapped_callback(request, *callback_args, **callback_kwargs)
  File "D:\Application\Anaconda\envs\ML\lib\site-packages\django\views\decorators\csrf.py", line 54, in wrapped_view
    return view_func(*args, **kwargs)
  File "D:\Application\Anaconda\envs\ML\lib\site-packages\rest_framework\viewsets.py", line 125, in view
    return self.dispatch(request, *args, **kwargs)
  File "D:\Application\Anaconda\envs\ML\lib\site-packages\rest_framework\views.py", line 511, in dispatch
    self.response = self.finalize_response(request, response, *args, **kwargs)
  File "D:\Application\Anaconda\envs\ML\lib\site-packages\rest_framework\views.py", line 423, in finalize_response
    assert isinstance(response, HttpResponseBase), (
AssertionError: Expected a `Response`, `HttpResponse` or `HttpStreamingResponse` to be returned from the view, but received a `<class 'NoneType'>`
[ERROR] 2022-04-28 09:47:46,826 log 224 Internal Server Error: /diabetes/fetch_diabetes_data/
Traceback (most recent call last):
  File "D:\Application\Anaconda\envs\ML\lib\site-packages\django\core\handlers\exception.py", line 47, in inner
    response = get_response(request)
  File "D:\Application\Anaconda\envs\ML\lib\site-packages\django\core\handlers\base.py", line 181, in _get_response
    response = wrapped_callback(request, *callback_args, **callback_kwargs)
  File "D:\Application\Anaconda\envs\ML\lib\site-packages\django\views\decorators\csrf.py", line 54, in wrapped_view
    return view_func(*args, **kwargs)
  File "D:\Application\Anaconda\envs\ML\lib\site-packages\rest_framework\viewsets.py", line 125, in view
    return self.dispatch(request, *args, **kwargs)
  File "D:\Application\Anaconda\envs\ML\lib\site-packages\rest_framework\views.py", line 511, in dispatch
    self.response = self.finalize_response(request, response, *args, **kwargs)
  File "D:\Application\Anaconda\envs\ML\lib\site-packages\rest_framework\views.py", line 423, in finalize_response
    assert isinstance(response, HttpResponseBase), (
AssertionError: Expected a `Response`, `HttpResponse` or `HttpStreamingResponse` to be returned from the view, but received a `<class 'NoneType'>`
[ERROR] 2022-04-28 09:48:32,238 log 224 Internal Server Error: /diabetes/fetch_diabetes_data/
Traceback (most recent call last):
  File "D:\Application\Anaconda\envs\ML\lib\site-packages\django\core\handlers\exception.py", line 47, in inner
    response = get_response(request)
  File "D:\Application\Anaconda\envs\ML\lib\site-packages\django\core\handlers\base.py", line 181, in _get_response
    response = wrapped_callback(request, *callback_args, **callback_kwargs)
  File "D:\Application\Anaconda\envs\ML\lib\site-packages\django\views\decorators\csrf.py", line 54, in wrapped_view
    return view_func(*args, **kwargs)
  File "D:\Application\Anaconda\envs\ML\lib\site-packages\rest_framework\viewsets.py", line 125, in view
    return self.dispatch(request, *args, **kwargs)
  File "D:\Application\Anaconda\envs\ML\lib\site-packages\rest_framework\views.py", line 511, in dispatch
    self.response = self.finalize_response(request, response, *args, **kwargs)
  File "D:\Application\Anaconda\envs\ML\lib\site-packages\rest_framework\views.py", line 423, in finalize_response
    assert isinstance(response, HttpResponseBase), (
AssertionError: Expected a `Response`, `HttpResponse` or `HttpStreamingResponse` to be returned from the view, but received a `<class 'NoneType'>`
[ERROR] 2022-04-28 09:50:33,838 log 224 Internal Server Error: /diabetes/fetch_diabetes_data/
Traceback (most recent call last):
  File "D:\Application\Anaconda\envs\ML\lib\site-packages\django\core\handlers\exception.py", line 47, in inner
    response = get_response(request)
  File "D:\Application\Anaconda\envs\ML\lib\site-packages\django\core\handlers\base.py", line 181, in _get_response
    response = wrapped_callback(request, *callback_args, **callback_kwargs)
  File "D:\Application\Anaconda\envs\ML\lib\site-packages\django\views\decorators\csrf.py", line 54, in wrapped_view
    return view_func(*args, **kwargs)
  File "D:\Application\Anaconda\envs\ML\lib\site-packages\rest_framework\viewsets.py", line 125, in view
    return self.dispatch(request, *args, **kwargs)
  File "D:\Application\Anaconda\envs\ML\lib\site-packages\rest_framework\views.py", line 511, in dispatch
    self.response = self.finalize_response(request, response, *args, **kwargs)
  File "D:\Application\Anaconda\envs\ML\lib\site-packages\rest_framework\views.py", line 423, in finalize_response
    assert isinstance(response, HttpResponseBase), (
AssertionError: Expected a `Response`, `HttpResponse` or `HttpStreamingResponse` to be returned from the view, but received a `<class 'NoneType'>`
[ERROR] 2022-04-28 09:50:51,265 log 224 Internal Server Error: /diabetes/fetch_diabetes_data/
Traceback (most recent call last):
  File "D:\Application\Anaconda\envs\ML\lib\site-packages\django\core\handlers\exception.py", line 47, in inner
    response = get_response(request)
  File "D:\Application\Anaconda\envs\ML\lib\site-packages\django\core\handlers\base.py", line 181, in _get_response
    response = wrapped_callback(request, *callback_args, **callback_kwargs)
  File "D:\Application\Anaconda\envs\ML\lib\site-packages\django\views\decorators\csrf.py", line 54, in wrapped_view
    return view_func(*args, **kwargs)
  File "D:\Application\Anaconda\envs\ML\lib\site-packages\rest_framework\viewsets.py", line 125, in view
    return self.dispatch(request, *args, **kwargs)
  File "D:\Application\Anaconda\envs\ML\lib\site-packages\rest_framework\views.py", line 511, in dispatch
    self.response = self.finalize_response(request, response, *args, **kwargs)
  File "D:\Application\Anaconda\envs\ML\lib\site-packages\rest_framework\views.py", line 423, in finalize_response
    assert isinstance(response, HttpResponseBase), (
AssertionError: Expected a `Response`, `HttpResponse` or `HttpStreamingResponse` to be returned from the view, but received a `<class 'NoneType'>`
[ERROR] 2022-04-28 09:51:12,844 log 224 Internal Server Error: /diabetes/fetch_diabetes_data/
Traceback (most recent call last):
  File "D:\Application\Anaconda\envs\ML\lib\site-packages\django\core\handlers\exception.py", line 47, in inner
    response = get_response(request)
  File "D:\Application\Anaconda\envs\ML\lib\site-packages\django\core\handlers\base.py", line 181, in _get_response
    response = wrapped_callback(request, *callback_args, **callback_kwargs)
  File "D:\Application\Anaconda\envs\ML\lib\site-packages\django\views\decorators\csrf.py", line 54, in wrapped_view
    return view_func(*args, **kwargs)
  File "D:\Application\Anaconda\envs\ML\lib\site-packages\rest_framework\viewsets.py", line 125, in view
    return self.dispatch(request, *args, **kwargs)
  File "D:\Application\Anaconda\envs\ML\lib\site-packages\rest_framework\views.py", line 511, in dispatch
    self.response = self.finalize_response(request, response, *args, **kwargs)
  File "D:\Application\Anaconda\envs\ML\lib\site-packages\rest_framework\views.py", line 423, in finalize_response
    assert isinstance(response, HttpResponseBase), (
AssertionError: Expected a `Response`, `HttpResponse` or `HttpStreamingResponse` to be returned from the view, but received a `<class 'NoneType'>`
[ERROR] 2022-04-28 09:52:53,256 log 224 Internal Server Error: /diabetes/fetch_diabetes_data/
Traceback (most recent call last):
  File "D:\Application\Anaconda\envs\ML\lib\site-packages\django\core\handlers\exception.py", line 47, in inner
    response = get_response(request)
  File "D:\Application\Anaconda\envs\ML\lib\site-packages\django\core\handlers\base.py", line 181, in _get_response
    response = wrapped_callback(request, *callback_args, **callback_kwargs)
  File "D:\Application\Anaconda\envs\ML\lib\site-packages\django\views\decorators\csrf.py", line 54, in wrapped_view
    return view_func(*args, **kwargs)
  File "D:\Application\Anaconda\envs\ML\lib\site-packages\rest_framework\viewsets.py", line 125, in view
    return self.dispatch(request, *args, **kwargs)
  File "D:\Application\Anaconda\envs\ML\lib\site-packages\rest_framework\views.py", line 511, in dispatch
    self.response = self.finalize_response(request, response, *args, **kwargs)
  File "D:\Application\Anaconda\envs\ML\lib\site-packages\rest_framework\views.py", line 423, in finalize_response
    assert isinstance(response, HttpResponseBase), (
AssertionError: Expected a `Response`, `HttpResponse` or `HttpStreamingResponse` to be returned from the view, but received a `<class 'NoneType'>`
[ERROR] 2022-04-28 09:53:49,197 views 41 用户admin1登录异常
[ERROR] 2022-04-28 09:54:08,079 log 224 Internal Server Error: /diabetes/fetch_diabetes_data/
Traceback (most recent call last):
  File "D:\Application\Anaconda\envs\ML\lib\site-packages\django\core\handlers\exception.py", line 47, in inner
    response = get_response(request)
  File "D:\Application\Anaconda\envs\ML\lib\site-packages\django\core\handlers\base.py", line 181, in _get_response
    response = wrapped_callback(request, *callback_args, **callback_kwargs)
  File "D:\Application\Anaconda\envs\ML\lib\site-packages\django\views\decorators\csrf.py", line 54, in wrapped_view
    return view_func(*args, **kwargs)
  File "D:\Application\Anaconda\envs\ML\lib\site-packages\rest_framework\viewsets.py", line 125, in view
    return self.dispatch(request, *args, **kwargs)
  File "D:\Application\Anaconda\envs\ML\lib\site-packages\rest_framework\views.py", line 511, in dispatch
    self.response = self.finalize_response(request, response, *args, **kwargs)
  File "D:\Application\Anaconda\envs\ML\lib\site-packages\rest_framework\views.py", line 423, in finalize_response
    assert isinstance(response, HttpResponseBase), (
AssertionError: Expected a `Response`, `HttpResponse` or `HttpStreamingResponse` to be returned from the view, but received a `<class 'NoneType'>`
[ERROR] 2022-04-28 09:55:03,731 views 41 用户admin1登录异常
[ERROR] 2022-04-28 09:57:51,608 log 224 Internal Server Error: /diabetes/fetch_diabetes_data/
Traceback (most recent call last):
  File "D:\Application\Anaconda\envs\ML\lib\site-packages\django\core\handlers\exception.py", line 47, in inner
    response = get_response(request)
  File "D:\Application\Anaconda\envs\ML\lib\site-packages\django\core\handlers\base.py", line 181, in _get_response
    response = wrapped_callback(request, *callback_args, **callback_kwargs)
  File "D:\Application\Anaconda\envs\ML\lib\site-packages\django\views\decorators\csrf.py", line 54, in wrapped_view
    return view_func(*args, **kwargs)
  File "D:\Application\Anaconda\envs\ML\lib\site-packages\rest_framework\viewsets.py", line 125, in view
    return self.dispatch(request, *args, **kwargs)
  File "D:\Application\Anaconda\envs\ML\lib\site-packages\rest_framework\views.py", line 511, in dispatch
    self.response = self.finalize_response(request, response, *args, **kwargs)
  File "D:\Application\Anaconda\envs\ML\lib\site-packages\rest_framework\views.py", line 423, in finalize_response
    assert isinstance(response, HttpResponseBase), (
AssertionError: Expected a `Response`, `HttpResponse` or `HttpStreamingResponse` to be returned from the view, but received a `<class 'NoneType'>`
[ERROR] 2022-04-29 14:31:54,146 views 54 Cannot assign "'1'": "Diabetes.user" must be a "User" instance.
[ERROR] 2022-04-29 14:32:15,738 views 54 Cannot assign "'1'": "Diabetes.user" must be a "User" instance.
[ERROR] 2022-04-29 17:31:34,529 views 84 When a serializer is passed a `data` keyword argument you must call `.is_valid()` before attempting to access the serialized `.data` representation.
You should either call `.is_valid()` first, or access `.initial_data` instead.
[ERROR] 2022-04-29 17:43:44,967 views 84 This QueryDict instance is immutable
[ERROR] 2022-04-29 17:45:17,660 views 84 This QueryDict instance is immutable
[ERROR] 2022-04-29 21:58:58,397 views 86 Cannot assign "'1'": "Diabetes.user" must be a "User" instance.
[ERROR] 2022-04-29 22:05:44,663 views 59 Traceback (most recent call last):
  File "D:\Application\Anaconda\envs\ML\lib\site-packages\django\db\models\fields\__init__.py", line 1823, in get_prep_value
    return int(value)
ValueError: invalid literal for int() with base 10: '{"token":"5c9ac76c6b5c179af307c7a709f0a1054cbd025c","user":"1","username":"admin"}'

The above exception was the direct cause of the following exception:

Traceback (most recent call last):
  File "E:\Projects\djangoProjects\keep_healthy\diabetes\views.py", line 52, in fetch_diabetes_data
    user = fetch_user_info(request).get('user')
  File "E:\Projects\djangoProjects\keep_healthy\common\request.py", line 6, in fetch_user_info
    user = User.objects.get(id=user_id)
  File "D:\Application\Anaconda\envs\ML\lib\site-packages\django\db\models\manager.py", line 85, in manager_method
    return getattr(self.get_queryset(), name)(*args, **kwargs)
ValueError: Field 'id' expected a number but got '{"token":"5c9ac76c6b5c179af307c7a709f0a1054cbd025c","user":"1","username":"admin"}'.

[ERROR] 2022-04-29 22:06:53,660 views 59 Traceback (most recent call last):
  File "E:\Projects\djangoProjects\keep_healthy\diabetes\views.py", line 52, in fetch_diabetes_data
    user = fetch_user_info(request).id
  File "E:\Projects\djangoProjects\keep_healthy\common\request.py", line 6, in fetch_user_info
    user = User.objects.get(id=auth['user'])
TypeError: string indices must be integers

[ERROR] 2022-04-29 22:07:24,716 views 59 Traceback (most recent call last):
  File "E:\Projects\djangoProjects\keep_healthy\diabetes\views.py", line 52, in fetch_diabetes_data
    user = fetch_user_info(request).id
  File "E:\Projects\djangoProjects\keep_healthy\common\request.py", line 6, in fetch_user_info
    user = User.objects.get(id=int(auth['user']))
TypeError: string indices must be integers

[ERROR] 2022-04-29 22:09:29,034 views 59 Traceback (most recent call last):
  File "E:\Projects\djangoProjects\keep_healthy\diabetes\views.py", line 52, in fetch_diabetes_data
    user = fetch_user_info(request).id
  File "E:\Projects\djangoProjects\keep_healthy\common\request.py", line 6, in fetch_user_info
    print(type(int(auth.get('user'))))
AttributeError: 'str' object has no attribute 'get'

[ERROR] 2022-04-29 22:09:44,259 views 59 Traceback (most recent call last):
  File "E:\Projects\djangoProjects\keep_healthy\diabetes\views.py", line 52, in fetch_diabetes_data
    user = fetch_user_info(request).id
  File "E:\Projects\djangoProjects\keep_healthy\common\request.py", line 6, in fetch_user_info
    print(type(int(auth.get('user'))))
AttributeError: 'str' object has no attribute 'get'

[ERROR] 2022-04-29 22:10:52,229 views 86 Cannot assign "1": "Diabetes.user" must be a "User" instance.
[ERROR] 2022-04-30 12:19:34,516 views 58 Traceback (most recent call last):
  File "E:\Projects\djangoProjects\keep_healthy\users\views.py", line 54, in login
    return response_success('登录成功', res)
NameError: name 'response_success' is not defined

[ERROR] 2022-04-30 12:19:35,090 log 224 Internal Server Error: /users/login/
Traceback (most recent call last):
  File "E:\Projects\djangoProjects\keep_healthy\users\views.py", line 54, in login
    return response_success('登录成功', res)
NameError: name 'response_success' is not defined

During handling of the above exception, another exception occurred:

Traceback (most recent call last):
  File "D:\Application\Anaconda\envs\ML\lib\site-packages\django\core\handlers\exception.py", line 47, in inner
    response = get_response(request)
  File "D:\Application\Anaconda\envs\ML\lib\site-packages\django\core\handlers\base.py", line 181, in _get_response
    response = wrapped_callback(request, *callback_args, **callback_kwargs)
  File "D:\Application\Anaconda\envs\ML\lib\site-packages\django\views\decorators\csrf.py", line 54, in wrapped_view
    return view_func(*args, **kwargs)
  File "D:\Application\Anaconda\envs\ML\lib\site-packages\rest_framework\viewsets.py", line 125, in view
    return self.dispatch(request, *args, **kwargs)
  File "D:\Application\Anaconda\envs\ML\lib\site-packages\rest_framework\views.py", line 509, in dispatch
    response = self.handle_exception(exc)
  File "D:\Application\Anaconda\envs\ML\lib\site-packages\rest_framework\views.py", line 469, in handle_exception
    self.raise_uncaught_exception(exc)
  File "D:\Application\Anaconda\envs\ML\lib\site-packages\rest_framework\views.py", line 480, in raise_uncaught_exception
    raise exc
  File "D:\Application\Anaconda\envs\ML\lib\site-packages\rest_framework\views.py", line 506, in dispatch
    response = handler(request, *args, **kwargs)
  File "E:\Projects\djangoProjects\keep_healthy\users\views.py", line 59, in login
    return response_failed(error)
NameError: name 'response_failed' is not defined
[ERROR] 2022-04-30 12:20:54,572 views 87 Error 10061 connecting to 47.98.97.198:6379. 由于目标计算机积极拒绝，无法连接。.
[ERROR] 2022-04-30 12:21:09,665 views 87 Error 10061 connecting to 47.98.97.198:6379. 由于目标计算机积极拒绝，无法连接。.
[ERROR] 2022-04-30 12:22:06,358 views 87 Error 10061 connecting to 47.98.97.198:6379. 由于目标计算机积极拒绝，无法连接。.
[ERROR] 2022-04-30 12:23:14,776 views 87 Traceback (most recent call last):
  File "D:\Application\Anaconda\envs\ML\lib\site-packages\django_redis\cache.py", line 31, in _decorator
    return method(self, *args, **kwargs)
  File "D:\Application\Anaconda\envs\ML\lib\site-packages\django_redis\cache.py", line 121, in get_many
    return self.client.get_many(*args, **kwargs)
  File "D:\Application\Anaconda\envs\ML\lib\site-packages\django_redis\client\default.py", line 483, in get_many
    raise ConnectionInterrupted(connection=client) from e
django_redis.exceptions.ConnectionInterrupted: Redis ConnectionError: Error 10061 connecting to 47.98.97.198:6379. 由于目标计算机积极拒绝，无法连接。.

During handling of the above exception, another exception occurred:

Traceback (most recent call last):
  File "E:\Projects\djangoProjects\keep_healthy\diabetes\views.py", line 77, in start_pred_diabetes
    df = read_frame(qs=test)
  File "D:\Application\Anaconda\envs\ML\lib\site-packages\django_pandas\io.py", line 136, in read_frame
    update_with_verbose(df, fieldnames, fields)
  File "D:\Application\Anaconda\envs\ML\lib\site-packages\django_pandas\utils.py", line 88, in update_with_verbose
    df[fieldname] = function(df[fieldname])
redis.exceptions.ConnectionError: Error 10061 connecting to 47.98.97.198:6379. 由于目标计算机积极拒绝，无法连接。.

[ERROR] 2022-04-30 12:29:32,779 views 87 Traceback (most recent call last):
  File "D:\Application\Anaconda\envs\ML\lib\site-packages\django_redis\cache.py", line 31, in _decorator
    return method(self, *args, **kwargs)
  File "D:\Application\Anaconda\envs\ML\lib\site-packages\django_redis\cache.py", line 121, in get_many
    return self.client.get_many(*args, **kwargs)
  File "D:\Application\Anaconda\envs\ML\lib\site-packages\django_redis\client\default.py", line 483, in get_many
    raise ConnectionInterrupted(connection=client) from e
django_redis.exceptions.ConnectionInterrupted: Redis ResponseError: DENIED Redis is running in protected mode because protected mode is enabled, no bind address was specified, no authentication password is requested to clients. In this mode connections are only accepted from the loopback interface. If you want to connect from external computers to Redis you may adopt one of the following solutions: 1) Just disable protected mode sending the command 'CONFIG SET protected-mode no' from the loopback interface by connecting to Redis from the same host the server is running, however MAKE SURE Redis is not publicly accessible from internet if you do so. Use CONFIG REWRITE to make this change permanent. 2) Alternatively you can just disable the protected mode by editing the Redis configuration file, and setting the protected mode option to 'no', and then restarting the server. 3) If you started the server manually just for testing, restart it with the '--protected-mode no' option. 4) Setup a bind address or an authentication password. NOTE: You only need to do one of the above things in order for the server to start accepting connections from the outside.

During handling of the above exception, another exception occurred:

Traceback (most recent call last):
  File "E:\Projects\djangoProjects\keep_healthy\diabetes\views.py", line 77, in start_pred_diabetes
    df = read_frame(qs=test)
  File "D:\Application\Anaconda\envs\ML\lib\site-packages\django_pandas\io.py", line 136, in read_frame
    update_with_verbose(df, fieldnames, fields)
  File "D:\Application\Anaconda\envs\ML\lib\site-packages\django_pandas\utils.py", line 88, in update_with_verbose
    df[fieldname] = function(df[fieldname])
redis.exceptions.ResponseError: DENIED Redis is running in protected mode because protected mode is enabled, no bind address was specified, no authentication password is requested to clients. In this mode connections are only accepted from the loopback interface. If you want to connect from external computers to Redis you may adopt one of the following solutions: 1) Just disable protected mode sending the command 'CONFIG SET protected-mode no' from the loopback interface by connecting to Redis from the same host the server is running, however MAKE SURE Redis is not publicly accessible from internet if you do so. Use CONFIG REWRITE to make this change permanent. 2) Alternatively you can just disable the protected mode by editing the Redis configuration file, and setting the protected mode option to 'no', and then restarting the server. 3) If you started the server manually just for testing, restart it with the '--protected-mode no' option. 4) Setup a bind address or an authentication password. NOTE: You only need to do one of the above things in order for the server to start accepting connections from the outside.

[ERROR] 2022-04-30 12:31:51,667 views 87 Traceback (most recent call last):
  File "D:\Application\Anaconda\envs\ML\lib\site-packages\django_redis\cache.py", line 31, in _decorator
    return method(self, *args, **kwargs)
  File "D:\Application\Anaconda\envs\ML\lib\site-packages\django_redis\cache.py", line 121, in get_many
    return self.client.get_many(*args, **kwargs)
  File "D:\Application\Anaconda\envs\ML\lib\site-packages\django_redis\client\default.py", line 483, in get_many
    raise ConnectionInterrupted(connection=client) from e
django_redis.exceptions.ConnectionInterrupted: Redis ResponseError: DENIED Redis is running in protected mode because protected mode is enabled, no bind address was specified, no authentication password is requested to clients. In this mode connections are only accepted from the loopback interface. If you want to connect from external computers to Redis you may adopt one of the following solutions: 1) Just disable protected mode sending the command 'CONFIG SET protected-mode no' from the loopback interface by connecting to Redis from the same host the server is running, however MAKE SURE Redis is not publicly accessible from internet if you do so. Use CONFIG REWRITE to make this change permanent. 2) Alternatively you can just disable the protected mode by editing the Redis configuration file, and setting the protected mode option to 'no', and then restarting the server. 3) If you started the server manually just for testing, restart it with the '--protected-mode no' option. 4) Setup a bind address or an authentication password. NOTE: You only need to do one of the above things in order for the server to start accepting connections from the outside.

During handling of the above exception, another exception occurred:

Traceback (most recent call last):
  File "E:\Projects\djangoProjects\keep_healthy\diabetes\views.py", line 77, in start_pred_diabetes
    df = read_frame(qs=test)
  File "D:\Application\Anaconda\envs\ML\lib\site-packages\django_pandas\io.py", line 136, in read_frame
    update_with_verbose(df, fieldnames, fields)
  File "D:\Application\Anaconda\envs\ML\lib\site-packages\django_pandas\utils.py", line 88, in update_with_verbose
    df[fieldname] = function(df[fieldname])
redis.exceptions.ResponseError: DENIED Redis is running in protected mode because protected mode is enabled, no bind address was specified, no authentication password is requested to clients. In this mode connections are only accepted from the loopback interface. If you want to connect from external computers to Redis you may adopt one of the following solutions: 1) Just disable protected mode sending the command 'CONFIG SET protected-mode no' from the loopback interface by connecting to Redis from the same host the server is running, however MAKE SURE Redis is not publicly accessible from internet if you do so. Use CONFIG REWRITE to make this change permanent. 2) Alternatively you can just disable the protected mode by editing the Redis configuration file, and setting the protected mode option to 'no', and then restarting the server. 3) If you started the server manually just for testing, restart it with the '--protected-mode no' option. 4) Setup a bind address or an authentication password. NOTE: You only need to do one of the above things in order for the server to start accepting connections from the outside.

[ERROR] 2022-04-30 12:39:01,034 views 87 Traceback (most recent call last):
  File "D:\Application\Anaconda\envs\ML\lib\site-packages\django_redis\cache.py", line 31, in _decorator
    return method(self, *args, **kwargs)
  File "D:\Application\Anaconda\envs\ML\lib\site-packages\django_redis\cache.py", line 121, in get_many
    return self.client.get_many(*args, **kwargs)
  File "D:\Application\Anaconda\envs\ML\lib\site-packages\django_redis\client\default.py", line 483, in get_many
    raise ConnectionInterrupted(connection=client) from e
django_redis.exceptions.ConnectionInterrupted: Redis ResponseError: DENIED Redis is running in protected mode because protected mode is enabled, no bind address was specified, no authentication password is requested to clients. In this mode connections are only accepted from the loopback interface. If you want to connect from external computers to Redis you may adopt one of the following solutions: 1) Just disable protected mode sending the command 'CONFIG SET protected-mode no' from the loopback interface by connecting to Redis from the same host the server is running, however MAKE SURE Redis is not publicly accessible from internet if you do so. Use CONFIG REWRITE to make this change permanent. 2) Alternatively you can just disable the protected mode by editing the Redis configuration file, and setting the protected mode option to 'no', and then restarting the server. 3) If you started the server manually just for testing, restart it with the '--protected-mode no' option. 4) Setup a bind address or an authentication password. NOTE: You only need to do one of the above things in order for the server to start accepting connections from the outside.

During handling of the above exception, another exception occurred:

Traceback (most recent call last):
  File "E:\Projects\djangoProjects\keep_healthy\diabetes\views.py", line 77, in start_pred_diabetes
    df = read_frame(qs=test)
  File "D:\Application\Anaconda\envs\ML\lib\site-packages\django_pandas\io.py", line 136, in read_frame
    update_with_verbose(df, fieldnames, fields)
  File "D:\Application\Anaconda\envs\ML\lib\site-packages\django_pandas\utils.py", line 88, in update_with_verbose
    df[fieldname] = function(df[fieldname])
redis.exceptions.ResponseError: DENIED Redis is running in protected mode because protected mode is enabled, no bind address was specified, no authentication password is requested to clients. In this mode connections are only accepted from the loopback interface. If you want to connect from external computers to Redis you may adopt one of the following solutions: 1) Just disable protected mode sending the command 'CONFIG SET protected-mode no' from the loopback interface by connecting to Redis from the same host the server is running, however MAKE SURE Redis is not publicly accessible from internet if you do so. Use CONFIG REWRITE to make this change permanent. 2) Alternatively you can just disable the protected mode by editing the Redis configuration file, and setting the protected mode option to 'no', and then restarting the server. 3) If you started the server manually just for testing, restart it with the '--protected-mode no' option. 4) Setup a bind address or an authentication password. NOTE: You only need to do one of the above things in order for the server to start accepting connections from the outside.

[ERROR] 2022-04-30 12:40:10,234 views 87 Traceback (most recent call last):
  File "D:\Application\Anaconda\envs\ML\lib\site-packages\django_redis\cache.py", line 31, in _decorator
    return method(self, *args, **kwargs)
  File "D:\Application\Anaconda\envs\ML\lib\site-packages\django_redis\cache.py", line 121, in get_many
    return self.client.get_many(*args, **kwargs)
  File "D:\Application\Anaconda\envs\ML\lib\site-packages\django_redis\client\default.py", line 483, in get_many
    raise ConnectionInterrupted(connection=client) from e
django_redis.exceptions.ConnectionInterrupted: Redis ResponseError: DENIED Redis is running in protected mode because protected mode is enabled, no bind address was specified, no authentication password is requested to clients. In this mode connections are only accepted from the loopback interface. If you want to connect from external computers to Redis you may adopt one of the following solutions: 1) Just disable protected mode sending the command 'CONFIG SET protected-mode no' from the loopback interface by connecting to Redis from the same host the server is running, however MAKE SURE Redis is not publicly accessible from internet if you do so. Use CONFIG REWRITE to make this change permanent. 2) Alternatively you can just disable the protected mode by editing the Redis configuration file, and setting the protected mode option to 'no', and then restarting the server. 3) If you started the server manually just for testing, restart it with the '--protected-mode no' option. 4) Setup a bind address or an authentication password. NOTE: You only need to do one of the above things in order for the server to start accepting connections from the outside.

During handling of the above exception, another exception occurred:

Traceback (most recent call last):
  File "E:\Projects\djangoProjects\keep_healthy\diabetes\views.py", line 77, in start_pred_diabetes
    df = read_frame(qs=test)
  File "D:\Application\Anaconda\envs\ML\lib\site-packages\django_pandas\io.py", line 136, in read_frame
    update_with_verbose(df, fieldnames, fields)
  File "D:\Application\Anaconda\envs\ML\lib\site-packages\django_pandas\utils.py", line 88, in update_with_verbose
    df[fieldname] = function(df[fieldname])
redis.exceptions.ResponseError: DENIED Redis is running in protected mode because protected mode is enabled, no bind address was specified, no authentication password is requested to clients. In this mode connections are only accepted from the loopback interface. If you want to connect from external computers to Redis you may adopt one of the following solutions: 1) Just disable protected mode sending the command 'CONFIG SET protected-mode no' from the loopback interface by connecting to Redis from the same host the server is running, however MAKE SURE Redis is not publicly accessible from internet if you do so. Use CONFIG REWRITE to make this change permanent. 2) Alternatively you can just disable the protected mode by editing the Redis configuration file, and setting the protected mode option to 'no', and then restarting the server. 3) If you started the server manually just for testing, restart it with the '--protected-mode no' option. 4) Setup a bind address or an authentication password. NOTE: You only need to do one of the above things in order for the server to start accepting connections from the outside.

[ERROR] 2022-04-30 15:03:25,696 views 88 Traceback (most recent call last):
  File "E:\Projects\djangoProjects\keep_healthy\diabetes\views.py", line 77, in start_pred_diabetes
    test = Diabetes.objects.filter(id=1).values(fields)
  File "D:\Application\Anaconda\envs\ML\lib\site-packages\django\db\models\query.py", line 840, in values
    clone = self._values(*fields, **expressions)
  File "D:\Application\Anaconda\envs\ML\lib\site-packages\django\db\models\query.py", line 835, in _values
    clone.query.set_values(fields)
TypeError: unhashable type: 'list'

[ERROR] 2022-04-30 15:10:16,397 views 92 Traceback (most recent call last):
  File "E:\Projects\djangoProjects\keep_healthy\diabetes\views.py", line 81, in start_pred_diabetes
    loaded_model = pickle.load(open("../utils/pima.pickle.dat", "rb"))
FileNotFoundError: [Errno 2] No such file or directory: '../utils/pima.pickle.dat'

[ERROR] 2022-04-30 15:10:24,104 views 92 Traceback (most recent call last):
  File "E:\Projects\djangoProjects\keep_healthy\diabetes\views.py", line 81, in start_pred_diabetes
    loaded_model = pickle.load(open("../utils/pima.pickle.dat", "rb"))
FileNotFoundError: [Errno 2] No such file or directory: '../utils/pima.pickle.dat'

[ERROR] 2022-04-30 15:11:57,605 views 92 Traceback (most recent call last):
  File "E:\Projects\djangoProjects\keep_healthy\diabetes\views.py", line 82, in start_pred_diabetes
    y_pred = loaded_model.predict(df)
  File "D:\Application\Anaconda\envs\ML\lib\site-packages\xgboost\sklearn.py", line 966, in predict
    test_dmatrix = DMatrix(data, base_margin=base_margin,
  File "D:\Application\Anaconda\envs\ML\lib\site-packages\xgboost\core.py", line 500, in __init__
    handle, feature_names, feature_types = dispatch_data_backend(
ValueError: DataFrame.dtypes for data must be int, float, bool or categorical.  When
                categorical type is supplied, DMatrix parameter
                `enable_categorical` must be set to `True`.insulin, bmi, pedigree_function

[ERROR] 2022-04-30 15:13:56,633 views 92 Traceback (most recent call last):
  File "E:\Projects\djangoProjects\keep_healthy\diabetes\views.py", line 82, in start_pred_diabetes
    y_pred = loaded_model.predict(df)
  File "D:\Application\Anaconda\envs\ML\lib\site-packages\xgboost\sklearn.py", line 970, in predict
    class_probs = self.get_booster().predict(
  File "D:\Application\Anaconda\envs\ML\lib\site-packages\xgboost\core.py", line 1485, in predict
    self._validate_features(data)
ValueError: feature_names mismatch: ['Pregnancies', 'Glucose', 'BloodPressure', 'SkinThickness', 'Insulin', 'BMI', 'DiabetesPedigreeFunction', 'Age'] ['pregnancies', 'glucose', 'blood_pressure', 'skin_thickness', 'insulin', 'bmi', 'pedigree_function', 'age', 'outcome']
expected Insulin, Glucose, SkinThickness, BloodPressure, BMI, Age, DiabetesPedigreeFunction, Pregnancies in input data
training data did not have the following fields: outcome, skin_thickness, pedigree_function, insulin, bmi, pregnancies, blood_pressure, age, glucose

[ERROR] 2022-04-30 15:26:57,285 views 97 Traceback (most recent call last):
  File "E:\Projects\djangoProjects\keep_healthy\diabetes\views.py", line 87, in start_pred_diabetes
    y_pred = loaded_model.predict(df)
  File "D:\Application\Anaconda\envs\ML\lib\site-packages\xgboost\sklearn.py", line 970, in predict
    class_probs = self.get_booster().predict(
  File "D:\Application\Anaconda\envs\ML\lib\site-packages\xgboost\core.py", line 1485, in predict
    self._validate_features(data)
ValueError: feature_names mismatch: ['Pregnancies', 'Glucose', 'BloodPressure', 'SkinThickness', 'Insulin', 'BMI', 'DiabetesPedigreeFunction', 'Age'] ['pregnancies', 'glucose', 'blood_pressure', 'skin_thickness', 'insulin', 'bmi', 'pedigree_function', 'age']
expected Pregnancies, DiabetesPedigreeFunction, Glucose, BMI, BloodPressure, Age, SkinThickness, Insulin in input data
training data did not have the following fields: glucose, bmi, pedigree_function, blood_pressure, insulin, skin_thickness, age, pregnancies

[ERROR] 2022-04-30 16:30:42,009 views 98 Traceback (most recent call last):
  File "E:\Projects\djangoProjects\keep_healthy\diabetes\views.py", line 86, in start_pred_diabetes
    pred = self.load_pred_model(test,fields)
  File "E:\Projects\djangoProjects\keep_healthy\diabetes\views.py", line 111, in load_pred_model
    result = y_pred.to_list()
AttributeError: 'numpy.ndarray' object has no attribute 'to_list'

[ERROR] 2022-04-30 16:36:52,401 views 100 Traceback (most recent call last):
  File "E:\Projects\djangoProjects\keep_healthy\diabetes\views.py", line 87, in start_pred_diabetes
    print(ser.data)
  File "D:\Application\Anaconda\envs\ML\lib\site-packages\rest_framework\serializers.py", line 548, in data
    ret = super().data
  File "D:\Application\Anaconda\envs\ML\lib\site-packages\rest_framework\serializers.py", line 246, in data
    self._data = self.to_representation(self.instance)
AssertionError: ("Creating a ModelSerializer without either the 'fields' attribute or the 'exclude' attribute has been deprecated since 3.3.0, and is now disallowed. Add an explicit fields = '__all__' to the DiabetesModelSerializer serializer.",)

[ERROR] 2022-04-30 18:40:35,817 views 106 Traceback (most recent call last):
  File "E:\Projects\djangoProjects\keep_healthy\diabetes\views.py", line 89, in start_pred_diabetes
    result = thread.result()
  File "D:\Application\Anaconda\envs\ML\lib\concurrent\futures\_base.py", line 432, in result
    return self.__get_result()
  File "D:\Application\Anaconda\envs\ML\lib\concurrent\futures\_base.py", line 388, in __get_result
    raise self._exception
AttributeError: 'Diabetes' object has no attribute '_iterable_class'

[ERROR] 2022-04-30 18:44:59,247 views 108 Traceback (most recent call last):
  File "E:\Projects\djangoProjects\keep_healthy\diabetes\views.py", line 90, in start_pred_diabetes
    print(thread.result())
  File "D:\Application\Anaconda\envs\ML\lib\concurrent\futures\_base.py", line 432, in result
    return self.__get_result()
  File "D:\Application\Anaconda\envs\ML\lib\concurrent\futures\_base.py", line 388, in __get_result
    raise self._exception
AttributeError: 'Diabetes' object has no attribute '_iterable_class'

[ERROR] 2022-04-30 18:47:20,693 views 108 Traceback (most recent call last):
  File "E:\Projects\djangoProjects\keep_healthy\diabetes\views.py", line 90, in start_pred_diabetes
    print(thread.result())
  File "D:\Application\Anaconda\envs\ML\lib\concurrent\futures\_base.py", line 432, in result
    return self.__get_result()
  File "D:\Application\Anaconda\envs\ML\lib\concurrent\futures\_base.py", line 388, in __get_result
    raise self._exception
AttributeError: 'Diabetes' object has no attribute '_iterable_class'

[ERROR] 2022-04-30 18:52:35,795 views 112 Traceback (most recent call last):
  File "E:\Projects\djangoProjects\keep_healthy\diabetes\views.py", line 92, in start_pred_diabetes
    print(thread.result())
  File "D:\Application\Anaconda\envs\ML\lib\concurrent\futures\_base.py", line 432, in result
    return self.__get_result()
  File "D:\Application\Anaconda\envs\ML\lib\concurrent\futures\_base.py", line 388, in __get_result
    raise self._exception
AttributeError: 'Diabetes' object has no attribute '_iterable_class'

[ERROR] 2022-04-30 18:53:50,268 views 112 Traceback (most recent call last):
  File "E:\Projects\djangoProjects\keep_healthy\diabetes\views.py", line 92, in start_pred_diabetes
    print(thread.result())
  File "D:\Application\Anaconda\envs\ML\lib\concurrent\futures\_base.py", line 432, in result
    return self.__get_result()
  File "D:\Application\Anaconda\envs\ML\lib\concurrent\futures\_base.py", line 388, in __get_result
    raise self._exception
AttributeError: 'Diabetes' object has no attribute '_iterable_class'

[ERROR] 2022-04-30 18:57:12,257 views 112 Traceback (most recent call last):
  File "E:\Projects\djangoProjects\keep_healthy\diabetes\views.py", line 92, in start_pred_diabetes
    print(thread.result())
  File "D:\Application\Anaconda\envs\ML\lib\concurrent\futures\_base.py", line 432, in result
    return self.__get_result()
  File "D:\Application\Anaconda\envs\ML\lib\concurrent\futures\_base.py", line 388, in __get_result
    raise self._exception
AttributeError: 'Diabetes' object has no attribute '_iterable_class'

[ERROR] 2022-04-30 18:57:51,723 views 112 Traceback (most recent call last):
  File "E:\Projects\djangoProjects\keep_healthy\diabetes\views.py", line 92, in start_pred_diabetes
    print(thread.result())
  File "D:\Application\Anaconda\envs\ML\lib\concurrent\futures\_base.py", line 432, in result
    return self.__get_result()
  File "D:\Application\Anaconda\envs\ML\lib\concurrent\futures\_base.py", line 388, in __get_result
    raise self._exception
AttributeError: 'Diabetes' object has no attribute '_iterable_class'

[ERROR] 2022-04-30 19:12:28,028 views 114 Traceback (most recent call last):
  File "E:\Projects\djangoProjects\keep_healthy\diabetes\views.py", line 100, in start_pred_diabetes
    print(result)
NameError: name 'result' is not defined

[ERROR] 2022-04-30 19:15:07,004 views 114 Traceback (most recent call last):
  File "E:\Projects\djangoProjects\keep_healthy\diabetes\views.py", line 88, in start_pred_diabetes
    thread = threadPool.submit(self.load_pred_model, diabetes.values(), fields=fields)
AttributeError: 'Diabetes' object has no attribute 'values'

[ERROR] 2022-04-30 19:43:22,722 views 116 Traceback (most recent call last):
  File "E:\Projects\djangoProjects\keep_healthy\diabetes\views.py", line 89, in start_pred_diabetes
    thread = threadPool.submit(self.load_pred_model,diabetes.objects.all(), fields=fields)
  File "D:\Application\Anaconda\envs\ML\lib\site-packages\django\db\models\manager.py", line 179, in __get__
    raise AttributeError("Manager isn't accessible via %s instances" % cls.__name__)
AttributeError: Manager isn't accessible via Diabetes instances

[ERROR] 2022-04-30 19:43:29,360 views 116 Traceback (most recent call last):
  File "E:\Projects\djangoProjects\keep_healthy\diabetes\views.py", line 89, in start_pred_diabetes
    thread = threadPool.submit(self.load_pred_model,diabetes.objects.all(), fields=fields)
  File "D:\Application\Anaconda\envs\ML\lib\site-packages\django\db\models\manager.py", line 179, in __get__
    raise AttributeError("Manager isn't accessible via %s instances" % cls.__name__)
AttributeError: Manager isn't accessible via Diabetes instances

[ERROR] 2022-04-30 19:44:32,641 views 116 Traceback (most recent call last):
  File "E:\Projects\djangoProjects\keep_healthy\diabetes\views.py", line 89, in start_pred_diabetes
    thread = threadPool.submit(self.load_pred_model,diabetes.objects.all(), fields=fields)
  File "D:\Application\Anaconda\envs\ML\lib\site-packages\django\db\models\manager.py", line 179, in __get__
    raise AttributeError("Manager isn't accessible via %s instances" % cls.__name__)
AttributeError: Manager isn't accessible via Diabetes instances

[ERROR] 2022-04-30 19:45:42,442 views 116 Traceback (most recent call last):
  File "E:\Projects\djangoProjects\keep_healthy\diabetes\views.py", line 89, in start_pred_diabetes
    thread = threadPool.submit(self.load_pred_model,diabetes.serializable_value(), fields=fields)
TypeError: serializable_value() missing 1 required positional argument: 'field_name'

[ERROR] 2022-04-30 20:00:31,982 exceptions 23 [<diabetes.views.DiabetesViewSet object at 0x000001DE88596910>] An error occurred in the current transaction. You can't execute queries until the end of the 'atomic' block.
[ERROR] 2022-04-30 20:00:31,985 log 224 Insufficient Storage: /diabetes/start_pred_diabetes/
[ERROR] 2022-04-30 20:18:11,730 views 139 Traceback (most recent call last):
  File "E:\Projects\djangoProjects\keep_healthy\diabetes\views.py", line 134, in load_pred_model
    y_pred = loaded_model.predict_proba(df)  # 和predict不同的是，predict_proba计算标签概率
  File "D:\Application\Anaconda\envs\ML\lib\site-packages\xgboost\sklearn.py", line 1016, in predict_proba
    test_dmatrix = DMatrix(X, base_margin=base_margin,
  File "D:\Application\Anaconda\envs\ML\lib\site-packages\xgboost\core.py", line 500, in __init__
    handle, feature_names, feature_types = dispatch_data_backend(
ValueError: DataFrame.dtypes for data must be int, float, bool or categorical.  When
                categorical type is supplied, DMatrix parameter
                `enable_categorical` must be set to `True`.pregnancies, glucose, blood_pressure, skin_thickness, insulin, bmi, pedigree_function, age

[ERROR] 2022-04-30 20:19:20,430 views 139 Traceback (most recent call last):
  File "E:\Projects\djangoProjects\keep_healthy\diabetes\views.py", line 132, in load_pred_model
    df = pd.DataFrame.from_dict(data, dtype=float)
  File "D:\Application\Anaconda\envs\ML\lib\site-packages\pandas\core\frame.py", line 1373, in from_dict
    return cls(data, index=index, columns=columns, dtype=dtype)
  File "D:\Application\Anaconda\envs\ML\lib\site-packages\pandas\core\frame.py", line 529, in __init__
    mgr = init_dict(data, index, columns, dtype=dtype)
ValueError: If using all scalar values, you must pass an index

[ERROR] 2022-04-30 20:20:22,804 views 139 Traceback (most recent call last):
  File "E:\Projects\djangoProjects\keep_healthy\diabetes\views.py", line 132, in load_pred_model
    df = pd.DataFrame.from_dict(data,orient='columns', dtype=float)
  File "D:\Application\Anaconda\envs\ML\lib\site-packages\pandas\core\frame.py", line 1373, in from_dict
    return cls(data, index=index, columns=columns, dtype=dtype)
  File "D:\Application\Anaconda\envs\ML\lib\site-packages\pandas\core\frame.py", line 529, in __init__
    mgr = init_dict(data, index, columns, dtype=dtype)
ValueError: If using all scalar values, you must pass an index

[ERROR] 2022-04-30 20:22:40,685 views 139 Traceback (most recent call last):
  File "E:\Projects\djangoProjects\keep_healthy\diabetes\views.py", line 131, in load_pred_model
    df = read_frame(qs=[data], coerce_float=True, fieldnames=fields)
  File "D:\Application\Anaconda\envs\ML\lib\site-packages\django_pandas\io.py", line 124, in read_frame
    if is_values_queryset(qs):
  File "D:\Application\Anaconda\envs\ML\lib\site-packages\django_pandas\io.py", line 39, in is_values_queryset
    return qs._iterable_class == django.db.models.query.ValuesIterable
AttributeError: 'list' object has no attribute '_iterable_class'

[ERROR] 2022-04-30 20:22:55,097 views 139 Traceback (most recent call last):
  File "E:\Projects\djangoProjects\keep_healthy\diabetes\views.py", line 131, in load_pred_model
    df = read_frame(qs=data, coerce_float=True, fieldnames=fields)
  File "D:\Application\Anaconda\envs\ML\lib\site-packages\django_pandas\io.py", line 124, in read_frame
    if is_values_queryset(qs):
  File "D:\Application\Anaconda\envs\ML\lib\site-packages\django_pandas\io.py", line 39, in is_values_queryset
    return qs._iterable_class == django.db.models.query.ValuesIterable
AttributeError: 'dict' object has no attribute '_iterable_class'

[ERROR] 2022-04-30 20:24:03,691 views 139 Traceback (most recent call last):
  File "E:\Projects\djangoProjects\keep_healthy\diabetes\views.py", line 132, in load_pred_model
    df = pd.DataFrame.from_dict(data, orient='columns', dtype=float)
  File "D:\Application\Anaconda\envs\ML\lib\site-packages\pandas\core\frame.py", line 1373, in from_dict
    return cls(data, index=index, columns=columns, dtype=dtype)
  File "D:\Application\Anaconda\envs\ML\lib\site-packages\pandas\core\frame.py", line 529, in __init__
    mgr = init_dict(data, index, columns, dtype=dtype)
ValueError: If using all scalar values, you must pass an index

[ERROR] 2022-04-30 20:29:33,523 exceptions 23 [<diabetes.views.DiabetesViewSet object at 0x0000017693A766A0>] An error occurred in the current transaction. You can't execute queries until the end of the 'atomic' block.
[ERROR] 2022-04-30 20:29:33,527 log 224 Insufficient Storage: /diabetes/start_pred_diabetes/
[ERROR] 2022-05-02 09:41:54,847 views 35 用户admin登录异常
[ERROR] 2022-05-02 09:42:02,177 views 35 用户admin1登录异常
[ERROR] 2022-05-02 10:32:09,248 exceptions 23 [<diabetes.views.DiabetesViewSet object at 0x00000240B4CB6D90>] An error occurred in the current transaction. You can't execute queries until the end of the 'atomic' block.
[ERROR] 2022-05-02 10:32:09,251 log 224 Insufficient Storage: /diabetes/start_pred_diabetes/
[ERROR] 2022-05-02 10:33:54,680 exceptions 23 [<diabetes.views.DiabetesViewSet object at 0x00000240B39232B0>] An error occurred in the current transaction. You can't execute queries until the end of the 'atomic' block.
[ERROR] 2022-05-02 10:33:54,682 log 224 Insufficient Storage: /diabetes/start_pred_diabetes/
[ERROR] 2022-05-02 17:57:55,660 log 224 Internal Server Error: /users/send_email
Traceback (most recent call last):
  File "D:\Application\Anaconda\envs\ML\lib\site-packages\django\core\handlers\exception.py", line 47, in inner
    response = get_response(request)
  File "D:\Application\Anaconda\envs\ML\lib\site-packages\django\utils\deprecation.py", line 116, in __call__
    response = self.process_request(request)
  File "D:\Application\Anaconda\envs\ML\lib\site-packages\django\middleware\common.py", line 54, in process_request
    path = self.get_full_path_with_slash(request)
  File "D:\Application\Anaconda\envs\ML\lib\site-packages\django\middleware\common.py", line 88, in get_full_path_with_slash
    raise RuntimeError(
RuntimeError: You called this URL via POST, but the URL doesn't end in a slash and you have APPEND_SLASH set. Django can't redirect to the slash URL while maintaining POST data. Change your form to point to 127.0.0.1:8000/users/send_email/ (note the trailing slash), or set APPEND_SLASH=False in your Django settings.
[ERROR] 2022-05-02 17:58:44,897 log 224 Internal Server Error: /users/send_email/
Traceback (most recent call last):
  File "D:\Application\Anaconda\envs\ML\lib\site-packages\django\core\handlers\exception.py", line 47, in inner
    response = get_response(request)
  File "D:\Application\Anaconda\envs\ML\lib\site-packages\django\core\handlers\base.py", line 181, in _get_response
    response = wrapped_callback(request, *callback_args, **callback_kwargs)
  File "D:\Application\Anaconda\envs\ML\lib\site-packages\django\views\decorators\csrf.py", line 54, in wrapped_view
    return view_func(*args, **kwargs)
  File "D:\Application\Anaconda\envs\ML\lib\site-packages\rest_framework\viewsets.py", line 125, in view
    return self.dispatch(request, *args, **kwargs)
  File "D:\Application\Anaconda\envs\ML\lib\site-packages\rest_framework\views.py", line 511, in dispatch
    self.response = self.finalize_response(request, response, *args, **kwargs)
  File "D:\Application\Anaconda\envs\ML\lib\site-packages\rest_framework\views.py", line 423, in finalize_response
    assert isinstance(response, HttpResponseBase), (
AssertionError: Expected a `Response`, `HttpResponse` or `HttpStreamingResponse` to be returned from the view, but received a `<class 'NoneType'>`
[ERROR] 2022-05-02 18:00:27,500 log 224 Internal Server Error: /users/send_email/
Traceback (most recent call last):
  File "D:\Application\Anaconda\envs\ML\lib\site-packages\django\core\handlers\exception.py", line 47, in inner
    response = get_response(request)
  File "D:\Application\Anaconda\envs\ML\lib\site-packages\django\core\handlers\base.py", line 181, in _get_response
    response = wrapped_callback(request, *callback_args, **callback_kwargs)
  File "D:\Application\Anaconda\envs\ML\lib\site-packages\django\views\decorators\csrf.py", line 54, in wrapped_view
    return view_func(*args, **kwargs)
  File "D:\Application\Anaconda\envs\ML\lib\site-packages\rest_framework\viewsets.py", line 125, in view
    return self.dispatch(request, *args, **kwargs)
  File "D:\Application\Anaconda\envs\ML\lib\site-packages\rest_framework\views.py", line 511, in dispatch
    self.response = self.finalize_response(request, response, *args, **kwargs)
  File "D:\Application\Anaconda\envs\ML\lib\site-packages\rest_framework\views.py", line 423, in finalize_response
    assert isinstance(response, HttpResponseBase), (
AssertionError: Expected a `Response`, `HttpResponse` or `HttpStreamingResponse` to be returned from the view, but received a `<class 'NoneType'>`
[ERROR] 2022-05-02 18:00:46,079 log 224 Internal Server Error: /users/send_email/
Traceback (most recent call last):
  File "D:\Application\Anaconda\envs\ML\lib\site-packages\django\core\handlers\exception.py", line 47, in inner
    response = get_response(request)
  File "D:\Application\Anaconda\envs\ML\lib\site-packages\django\core\handlers\base.py", line 181, in _get_response
    response = wrapped_callback(request, *callback_args, **callback_kwargs)
  File "D:\Application\Anaconda\envs\ML\lib\site-packages\django\views\decorators\csrf.py", line 54, in wrapped_view
    return view_func(*args, **kwargs)
  File "D:\Application\Anaconda\envs\ML\lib\site-packages\rest_framework\viewsets.py", line 125, in view
    return self.dispatch(request, *args, **kwargs)
  File "D:\Application\Anaconda\envs\ML\lib\site-packages\rest_framework\views.py", line 511, in dispatch
    self.response = self.finalize_response(request, response, *args, **kwargs)
  File "D:\Application\Anaconda\envs\ML\lib\site-packages\rest_framework\views.py", line 423, in finalize_response
    assert isinstance(response, HttpResponseBase), (
AssertionError: Expected a `Response`, `HttpResponse` or `HttpStreamingResponse` to be returned from the view, but received a `<class 'NoneType'>`
[ERROR] 2022-05-02 18:01:42,634 log 224 Internal Server Error: /users/send_email/
Traceback (most recent call last):
  File "D:\Application\Anaconda\envs\ML\lib\site-packages\django\core\handlers\exception.py", line 47, in inner
    response = get_response(request)
  File "D:\Application\Anaconda\envs\ML\lib\site-packages\django\core\handlers\base.py", line 181, in _get_response
    response = wrapped_callback(request, *callback_args, **callback_kwargs)
  File "D:\Application\Anaconda\envs\ML\lib\site-packages\django\views\decorators\csrf.py", line 54, in wrapped_view
    return view_func(*args, **kwargs)
  File "D:\Application\Anaconda\envs\ML\lib\site-packages\rest_framework\viewsets.py", line 125, in view
    return self.dispatch(request, *args, **kwargs)
  File "D:\Application\Anaconda\envs\ML\lib\site-packages\rest_framework\views.py", line 511, in dispatch
    self.response = self.finalize_response(request, response, *args, **kwargs)
  File "D:\Application\Anaconda\envs\ML\lib\site-packages\rest_framework\views.py", line 423, in finalize_response
    assert isinstance(response, HttpResponseBase), (
AssertionError: Expected a `Response`, `HttpResponse` or `HttpStreamingResponse` to be returned from the view, but received a `<class 'NoneType'>`
[ERROR] 2022-05-02 18:02:32,808 log 224 Internal Server Error: /users/send_email/
Traceback (most recent call last):
  File "D:\Application\Anaconda\envs\ML\lib\site-packages\django\core\handlers\exception.py", line 47, in inner
    response = get_response(request)
  File "D:\Application\Anaconda\envs\ML\lib\site-packages\django\core\handlers\base.py", line 181, in _get_response
    response = wrapped_callback(request, *callback_args, **callback_kwargs)
  File "D:\Application\Anaconda\envs\ML\lib\site-packages\django\views\decorators\csrf.py", line 54, in wrapped_view
    return view_func(*args, **kwargs)
  File "D:\Application\Anaconda\envs\ML\lib\site-packages\rest_framework\viewsets.py", line 125, in view
    return self.dispatch(request, *args, **kwargs)
  File "D:\Application\Anaconda\envs\ML\lib\site-packages\rest_framework\views.py", line 511, in dispatch
    self.response = self.finalize_response(request, response, *args, **kwargs)
  File "D:\Application\Anaconda\envs\ML\lib\site-packages\rest_framework\views.py", line 423, in finalize_response
    assert isinstance(response, HttpResponseBase), (
AssertionError: Expected a `Response`, `HttpResponse` or `HttpStreamingResponse` to be returned from the view, but received a `<class 'NoneType'>`
[ERROR] 2022-05-02 18:04:31,448 log 224 Internal Server Error: /users/send_email/
Traceback (most recent call last):
  File "D:\Application\Anaconda\envs\ML\lib\site-packages\django\core\handlers\exception.py", line 47, in inner
    response = get_response(request)
  File "D:\Application\Anaconda\envs\ML\lib\site-packages\django\core\handlers\base.py", line 181, in _get_response
    response = wrapped_callback(request, *callback_args, **callback_kwargs)
  File "D:\Application\Anaconda\envs\ML\lib\site-packages\django\views\decorators\csrf.py", line 54, in wrapped_view
    return view_func(*args, **kwargs)
  File "D:\Application\Anaconda\envs\ML\lib\site-packages\rest_framework\viewsets.py", line 125, in view
    return self.dispatch(request, *args, **kwargs)
  File "D:\Application\Anaconda\envs\ML\lib\site-packages\rest_framework\views.py", line 511, in dispatch
    self.response = self.finalize_response(request, response, *args, **kwargs)
  File "D:\Application\Anaconda\envs\ML\lib\site-packages\rest_framework\views.py", line 423, in finalize_response
    assert isinstance(response, HttpResponseBase), (
AssertionError: Expected a `Response`, `HttpResponse` or `HttpStreamingResponse` to be returned from the view, but received a `<class 'NoneType'>`
[ERROR] 2022-05-02 18:06:36,172 log 224 Internal Server Error: /users/send_email/
Traceback (most recent call last):
  File "D:\Application\Anaconda\envs\ML\lib\site-packages\django\core\handlers\exception.py", line 47, in inner
    response = get_response(request)
  File "D:\Application\Anaconda\envs\ML\lib\site-packages\django\core\handlers\base.py", line 181, in _get_response
    response = wrapped_callback(request, *callback_args, **callback_kwargs)
  File "D:\Application\Anaconda\envs\ML\lib\site-packages\django\views\decorators\csrf.py", line 54, in wrapped_view
    return view_func(*args, **kwargs)
  File "D:\Application\Anaconda\envs\ML\lib\site-packages\rest_framework\viewsets.py", line 125, in view
    return self.dispatch(request, *args, **kwargs)
  File "D:\Application\Anaconda\envs\ML\lib\site-packages\rest_framework\views.py", line 511, in dispatch
    self.response = self.finalize_response(request, response, *args, **kwargs)
  File "D:\Application\Anaconda\envs\ML\lib\site-packages\rest_framework\views.py", line 423, in finalize_response
    assert isinstance(response, HttpResponseBase), (
AssertionError: Expected a `Response`, `HttpResponse` or `HttpStreamingResponse` to be returned from the view, but received a `<class 'NoneType'>`
[ERROR] 2022-05-02 18:10:05,165 log 224 Internal Server Error: /users/send_email/
Traceback (most recent call last):
  File "D:\Application\Anaconda\envs\ML\lib\site-packages\django\core\handlers\exception.py", line 47, in inner
    response = get_response(request)
  File "D:\Application\Anaconda\envs\ML\lib\site-packages\django\core\handlers\base.py", line 181, in _get_response
    response = wrapped_callback(request, *callback_args, **callback_kwargs)
  File "D:\Application\Anaconda\envs\ML\lib\site-packages\django\views\decorators\csrf.py", line 54, in wrapped_view
    return view_func(*args, **kwargs)
  File "D:\Application\Anaconda\envs\ML\lib\site-packages\rest_framework\viewsets.py", line 125, in view
    return self.dispatch(request, *args, **kwargs)
  File "D:\Application\Anaconda\envs\ML\lib\site-packages\rest_framework\views.py", line 511, in dispatch
    self.response = self.finalize_response(request, response, *args, **kwargs)
  File "D:\Application\Anaconda\envs\ML\lib\site-packages\rest_framework\views.py", line 423, in finalize_response
    assert isinstance(response, HttpResponseBase), (
AssertionError: Expected a `Response`, `HttpResponse` or `HttpStreamingResponse` to be returned from the view, but received a `<class 'NoneType'>`
[ERROR] 2022-05-02 18:11:05,935 log 224 Internal Server Error: /users/send_email/
Traceback (most recent call last):
  File "D:\Application\Anaconda\envs\ML\lib\site-packages\django\core\handlers\exception.py", line 47, in inner
    response = get_response(request)
  File "D:\Application\Anaconda\envs\ML\lib\site-packages\django\core\handlers\base.py", line 181, in _get_response
    response = wrapped_callback(request, *callback_args, **callback_kwargs)
  File "D:\Application\Anaconda\envs\ML\lib\site-packages\django\views\decorators\csrf.py", line 54, in wrapped_view
    return view_func(*args, **kwargs)
  File "D:\Application\Anaconda\envs\ML\lib\site-packages\rest_framework\viewsets.py", line 125, in view
    return self.dispatch(request, *args, **kwargs)
  File "D:\Application\Anaconda\envs\ML\lib\site-packages\rest_framework\views.py", line 511, in dispatch
    self.response = self.finalize_response(request, response, *args, **kwargs)
  File "D:\Application\Anaconda\envs\ML\lib\site-packages\rest_framework\views.py", line 423, in finalize_response
    assert isinstance(response, HttpResponseBase), (
AssertionError: Expected a `Response`, `HttpResponse` or `HttpStreamingResponse` to be returned from the view, but received a `<class 'NoneType'>`
[ERROR] 2022-05-03 10:19:47,694 views 75 Traceback (most recent call last):
  File "D:\Application\Anaconda\envs\ML\lib\site-packages\kombu\serialization.py", line 39, in _reraise_errors
    yield
  File "D:\Application\Anaconda\envs\ML\lib\site-packages\kombu\serialization.py", line 210, in dumps
    payload = encoder(data)
  File "D:\Application\Anaconda\envs\ML\lib\site-packages\kombu\utils\json.py", line 68, in dumps
    return _dumps(s, cls=cls or _default_encoder,
TypeError: Object of type Request is not JSON serializable

During handling of the above exception, another exception occurred:

Traceback (most recent call last):
  File "E:\Projects\djangoProjects\keep_healthy\users\views.py", line 69, in send_email
    tasks.send_mail_code.delay(request, email)
  File "D:\Application\Anaconda\envs\ML\lib\site-packages\celery\app\task.py", line 425, in delay
    return self.apply_async(args, kwargs)
  File "D:\Application\Anaconda\envs\ML\lib\site-packages\celery\app\task.py", line 575, in apply_async
    return app.send_task(
kombu.exceptions.EncodeError: Object of type Request is not JSON serializable

[ERROR] 2022-05-03 10:22:58,111 views 75 Traceback (most recent call last):
  File "D:\Application\Anaconda\envs\ML\lib\site-packages\kombu\utils\functional.py", line 30, in __call__
    return self.__value__
AttributeError: 'ChannelPromise' object has no attribute '__value__'

During handling of the above exception, another exception occurred:

Traceback (most recent call last):
  File "D:\Application\Anaconda\envs\ML\lib\site-packages\kombu\transport\virtual\base.py", line 925, in create_channel
    return self._avail_channels.pop()
IndexError: pop from empty list

During handling of the above exception, another exception occurred:

Traceback (most recent call last):
  File "D:\Application\Anaconda\envs\ML\lib\site-packages\redis\connection.py", line 559, in connect
    sock = self._connect()
  File "D:\Application\Anaconda\envs\ML\lib\site-packages\redis\connection.py", line 615, in _connect
    raise err
  File "D:\Application\Anaconda\envs\ML\lib\site-packages\redis\connection.py", line 603, in _connect
    sock.connect(socket_address)
TimeoutError: [WinError 10060] 由于连接方在一段时间后没有正确答复或连接的主机没有反应，连接尝试失败。

During handling of the above exception, another exception occurred:

Traceback (most recent call last):
  File "D:\Application\Anaconda\envs\ML\lib\site-packages\kombu\connection.py", line 446, in _reraise_as_library_errors
    yield
  File "D:\Application\Anaconda\envs\ML\lib\site-packages\kombu\connection.py", line 433, in _ensure_connection
    return retry_over_time(
  File "D:\Application\Anaconda\envs\ML\lib\site-packages\kombu\utils\functional.py", line 312, in retry_over_time
    return fun(*args, **kwargs)
redis.exceptions.ConnectionError: Error 10060 connecting to 47.98.97.198:6379. 由于连接方在一段时间后没有正确答复或连接的主机没有反应，连接尝试失败。.

The above exception was the direct cause of the following exception:

Traceback (most recent call last):
  File "E:\Projects\djangoProjects\keep_healthy\users\views.py", line 69, in send_email
    tasks.send_mail_code.delay(email)
  File "D:\Application\Anaconda\envs\ML\lib\site-packages\celery\app\task.py", line 425, in delay
    return self.apply_async(args, kwargs)
  File "D:\Application\Anaconda\envs\ML\lib\site-packages\celery\app\task.py", line 575, in apply_async
    return app.send_task(
kombu.exceptions.OperationalError: Error 10060 connecting to 47.98.97.198:6379. 由于连接方在一段时间后没有正确答复或连接的主机没有反应，连接尝试失败。.

[ERROR] 2022-05-03 10:28:50,905 views 75 Traceback (most recent call last):
  File "D:\Application\Anaconda\envs\ML\lib\site-packages\kombu\utils\functional.py", line 30, in __call__
    return self.__value__
AttributeError: 'ChannelPromise' object has no attribute '__value__'

During handling of the above exception, another exception occurred:

Traceback (most recent call last):
  File "D:\Application\Anaconda\envs\ML\lib\site-packages\kombu\transport\virtual\base.py", line 925, in create_channel
    return self._avail_channels.pop()
IndexError: pop from empty list

During handling of the above exception, another exception occurred:

Traceback (most recent call last):
  File "D:\Application\Anaconda\envs\ML\lib\site-packages\redis\connection.py", line 559, in connect
    sock = self._connect()
  File "D:\Application\Anaconda\envs\ML\lib\site-packages\redis\connection.py", line 615, in _connect
    raise err
  File "D:\Application\Anaconda\envs\ML\lib\site-packages\redis\connection.py", line 603, in _connect
    sock.connect(socket_address)
TimeoutError: [WinError 10060] 由于连接方在一段时间后没有正确答复或连接的主机没有反应，连接尝试失败。

During handling of the above exception, another exception occurred:

Traceback (most recent call last):
  File "D:\Application\Anaconda\envs\ML\lib\site-packages\kombu\connection.py", line 446, in _reraise_as_library_errors
    yield
  File "D:\Application\Anaconda\envs\ML\lib\site-packages\kombu\connection.py", line 433, in _ensure_connection
    return retry_over_time(
  File "D:\Application\Anaconda\envs\ML\lib\site-packages\kombu\utils\functional.py", line 312, in retry_over_time
    return fun(*args, **kwargs)
redis.exceptions.ConnectionError: Error 10060 connecting to 47.98.97.198:6379. 由于连接方在一段时间后没有正确答复或连接的主机没有反应，连接尝试失败。.

The above exception was the direct cause of the following exception:

Traceback (most recent call last):
  File "E:\Projects\djangoProjects\keep_healthy\users\views.py", line 69, in send_email
    tasks.send_mail_code.delay(email)
  File "D:\Application\Anaconda\envs\ML\lib\site-packages\celery\app\task.py", line 425, in delay
    return self.apply_async(args, kwargs)
  File "D:\Application\Anaconda\envs\ML\lib\site-packages\celery\app\task.py", line 575, in apply_async
    return app.send_task(
kombu.exceptions.OperationalError: Error 10060 connecting to 47.98.97.198:6379. 由于连接方在一段时间后没有正确答复或连接的主机没有反应，连接尝试失败。.

[ERROR] 2022-05-03 10:40:46,691 views 75 Traceback (most recent call last):
  File "D:\Application\Anaconda\envs\ML\lib\site-packages\kombu\utils\functional.py", line 30, in __call__
    return self.__value__
AttributeError: 'ChannelPromise' object has no attribute '__value__'

During handling of the above exception, another exception occurred:

Traceback (most recent call last):
  File "D:\Application\Anaconda\envs\ML\lib\site-packages\kombu\transport\virtual\base.py", line 925, in create_channel
    return self._avail_channels.pop()
IndexError: pop from empty list

During handling of the above exception, another exception occurred:

Traceback (most recent call last):
  File "D:\Application\Anaconda\envs\ML\lib\site-packages\redis\connection.py", line 559, in connect
    sock = self._connect()
  File "D:\Application\Anaconda\envs\ML\lib\site-packages\redis\connection.py", line 615, in _connect
    raise err
  File "D:\Application\Anaconda\envs\ML\lib\site-packages\redis\connection.py", line 603, in _connect
    sock.connect(socket_address)
TimeoutError: [WinError 10060] 由于连接方在一段时间后没有正确答复或连接的主机没有反应，连接尝试失败。

During handling of the above exception, another exception occurred:

Traceback (most recent call last):
  File "D:\Application\Anaconda\envs\ML\lib\site-packages\kombu\connection.py", line 446, in _reraise_as_library_errors
    yield
  File "D:\Application\Anaconda\envs\ML\lib\site-packages\kombu\connection.py", line 433, in _ensure_connection
    return retry_over_time(
  File "D:\Application\Anaconda\envs\ML\lib\site-packages\kombu\utils\functional.py", line 312, in retry_over_time
    return fun(*args, **kwargs)
redis.exceptions.ConnectionError: Error 10060 connecting to 47.98.97.198:6379. 由于连接方在一段时间后没有正确答复或连接的主机没有反应，连接尝试失败。.

The above exception was the direct cause of the following exception:

Traceback (most recent call last):
  File "E:\Projects\djangoProjects\keep_healthy\users\views.py", line 69, in send_email
    tasks.send_mail_code.delay(email)
  File "D:\Application\Anaconda\envs\ML\lib\site-packages\celery\app\task.py", line 425, in delay
    return self.apply_async(args, kwargs)
  File "D:\Application\Anaconda\envs\ML\lib\site-packages\celery\app\task.py", line 575, in apply_async
    return app.send_task(
kombu.exceptions.OperationalError: Error 10060 connecting to 47.98.97.198:6379. 由于连接方在一段时间后没有正确答复或连接的主机没有反应，连接尝试失败。.

[ERROR] 2022-05-03 11:05:58,883 views 75 Traceback (most recent call last):
  File "D:\Application\Anaconda\envs\ML\lib\site-packages\kombu\utils\functional.py", line 30, in __call__
    return self.__value__
AttributeError: 'ChannelPromise' object has no attribute '__value__'

During handling of the above exception, another exception occurred:

Traceback (most recent call last):
  File "D:\Application\Anaconda\envs\ML\lib\site-packages\kombu\connection.py", line 446, in _reraise_as_library_errors
    yield
  File "D:\Application\Anaconda\envs\ML\lib\site-packages\kombu\connection.py", line 433, in _ensure_connection
    return retry_over_time(
  File "D:\Application\Anaconda\envs\ML\lib\site-packages\kombu\utils\functional.py", line 312, in retry_over_time
    return fun(*args, **kwargs)
ConnectionRefusedError: [WinError 10061] 由于目标计算机积极拒绝，无法连接。

The above exception was the direct cause of the following exception:

Traceback (most recent call last):
  File "E:\Projects\djangoProjects\keep_healthy\users\views.py", line 69, in send_email
    tasks.send_mail_code.delay(email)
  File "D:\Application\Anaconda\envs\ML\lib\site-packages\celery\app\task.py", line 425, in delay
    return self.apply_async(args, kwargs)
  File "D:\Application\Anaconda\envs\ML\lib\site-packages\celery\app\task.py", line 575, in apply_async
    return app.send_task(
kombu.exceptions.OperationalError: [WinError 10061] 由于目标计算机积极拒绝，无法连接。

[ERROR] 2022-05-03 11:06:15,755 views 75 Traceback (most recent call last):
  File "D:\Application\Anaconda\envs\ML\lib\site-packages\kombu\utils\functional.py", line 30, in __call__
    return self.__value__
AttributeError: 'ChannelPromise' object has no attribute '__value__'

During handling of the above exception, another exception occurred:

Traceback (most recent call last):
  File "D:\Application\Anaconda\envs\ML\lib\site-packages\kombu\connection.py", line 446, in _reraise_as_library_errors
    yield
  File "D:\Application\Anaconda\envs\ML\lib\site-packages\kombu\connection.py", line 433, in _ensure_connection
    return retry_over_time(
  File "D:\Application\Anaconda\envs\ML\lib\site-packages\kombu\utils\functional.py", line 312, in retry_over_time
    return fun(*args, **kwargs)
ConnectionRefusedError: [WinError 10061] 由于目标计算机积极拒绝，无法连接。

The above exception was the direct cause of the following exception:

Traceback (most recent call last):
  File "E:\Projects\djangoProjects\keep_healthy\users\views.py", line 69, in send_email
    tasks.send_mail_code.delay(email)
  File "D:\Application\Anaconda\envs\ML\lib\site-packages\celery\app\task.py", line 425, in delay
    return self.apply_async(args, kwargs)
  File "D:\Application\Anaconda\envs\ML\lib\site-packages\celery\app\task.py", line 575, in apply_async
    return app.send_task(
kombu.exceptions.OperationalError: [WinError 10061] 由于目标计算机积极拒绝，无法连接。

